Workbook

Sheet Dashboard
B1: 📊 DASHBOARD — Natural Mix
B3: 📅 Filtro de Mês: | E3: Setembro | G3: ⬅ Selecione o mês para atualizar
C6: 💸 | D6: Despesas | F6: 📊 | G6: Margem
D7: =SUMIF(Despesas_DB!C4:C99,$E$3,Despesas_DB!H4:H99) -> 1943 | G7: =IFERROR(D13/J10,0) -> 0.45281478
C9: 🛒 | D9: Pedidos | F9: 🎯 | G9: Ticket | J9: 💰 Faturamento
D10: =COUNTIF(Pedidos_DB!C4:C110,$E$3) -> 11 | G10: =IFERROR(J10/D10,0) -> 322.80909 | J10: =SUMIF(Pedidos_DB!C4:C110,$E$3,Pedidos_DB!G4:G110) -> 3550.9
C12: 📈 | D12: Lucro | F12: ✅ | G12: Concluídos
D13: =J10-D7 -> 1607.9 | G13: =SUMPRODUCT((Pedidos_DB!C4:C110=$E$3)*(LOWER(Pedidos_DB!H4:H110)="concluído")) -> 11
Q21: =C49 -> 0 | R21: =G49 -> 0
Q22: =C50 -> 0 | R22: =G50 -> 0
C64: Selecione o mês em D4 • Projeto de Extensão — Análise de Dados

Sheet Pedidos
B1: 🛒 CONTROLE DE PEDIDOS
B2: 📅 Filtro de Mês: | D2: Setembro | G2: ⬅ Selecione o mês para atualizar
B4: 💰 Faturamento | D4: 🛒 Pedidos | F4: ✅ Concluídos | H4: ⏳ Pendentes | J4: 🎯 Ticket Médio | K4: 🔄 Processo
B5: =SUMIF(Pedidos_DB!C4:C110,$D$2,Pedidos_DB!G4:G110) -> 3550.9 | D5: =COUNTIF(Pedidos_DB!C4:C110,$D$2) -> 11 | F5: =SUMPRODUCT((Pedidos_DB!C4:C110=$D$2)*(LOWER(Pedidos_DB!H4:H110)="concluído")) -> 11 | H5: =SUMPRODUCT((Pedidos_DB!C4:C110=$D$2)*(LOWER(Pedidos_DB!H4:H110)="pendente")) -> 0 | J5: =IFERROR(B5/D5,0) -> 322.80909 | K5: =SUMPRODUCT((Pedidos_DB!C4:C110=$D$2)*(LOWER(Pedidos_DB!H4:H110)="processo")) -> 0
B8: 📋 Pedidos do Mês Selecionado | J8: 🏪 Fat. por Salão
B9: Data | C9: Mês | D9: Cliente/Salão | E9: Produto | F9: Qtd | G9: Valor (R$) | H9: Status | J9: Salão | L9: Valor (R$)
B10: =IFERROR(IF(INDEX(Pedidos_DB!C:C,3+MATCH($D$2,Pedidos_DB!C4:C110,0)+0)<>$D$2,"",INDEX(Pedidos_DB!B:B,3+MATCH($D$2,Pedidos_DB!C4:C110,0)+0)),"") -> 2024-09-03 | C10: =IFERROR(IF(INDEX(Pedidos_DB!C:C,3+MATCH($D$2,Pedidos_DB!C4:C110,0)+0)<>$D$2,"",INDEX(Pedidos_DB!C:C,3+MATCH($D$2,Pedidos_DB!C4:C110,0)+0)),"") -> Setembro | D10: =IFERROR(IF(INDEX(Pedidos_DB!C:C,3+MATCH($D$2,Pedidos_DB!C4:C110,0)+0)<>$D$2,"",INDEX(Pedidos_DB!D:D,3+MATCH($D$2,Pedidos_DB!C4:C110,0)+0)),"") -> Salão Glamour | E10: =IFERROR(IF(INDEX(Pedidos_DB!C:C,3+MATCH($D$2,Pedidos_DB!C4:C110,0)+0)<>$D$2,"",INDEX(Pedidos_DB!E:E,3+MATCH($D$2,Pedidos_DB!C4:C110,0)+0)),"") -> Shampoo Antiqueda | F10: =IFERROR(IF(INDEX(Pedidos_DB!C:C,3+MATCH($D$2,Pedidos_DB!C4:C110,0)+0)<>$D$2,"",INDEX(Pedidos_DB!F:F,3+MATCH($D$2,Pedidos_DB!C4:C110,0)+0)),"") -> 15 | G10: =IFERROR(IF(INDEX(Pedidos_DB!C:C,3+MATCH($D$2,Pedidos_DB!C4:C110,0)+0)<>$D$2,"",INDEX(Pedidos_DB!G:G,3+MATCH($D$2,Pedidos_DB!C4:C110,0)+0)),"") -> 283.5 | H10: =IFERROR(IF(INDEX(Pedidos_DB!C:C,3+MATCH($D$2,Pedidos_DB!C4:C110,0)+0)<>$D$2,"",INDEX(Pedidos_DB!H:H,3+MATCH($D$2,Pedidos_DB!C4:C110,0)+0)),"") -> concluído | J10: Salão Beleza & Cia | L10: =SUMPRODUCT((Pedidos_DB!C4:C110=$D$2)*(Pedidos_DB!D4:D110=J10)*Pedidos_DB!G4:G110) -> 545
B11: =IFERROR(IF(INDEX(Pedidos_DB!C:C,3+MATCH($D$2,Pedidos_DB!C4:C110,0)+1)<>$D$2,"",INDEX(Pedidos_DB!B:B,3+MATCH($D$2,Pedidos_DB!C4:C110,0)+1)),"") -> 2024-09-05 | C11: =IFERROR(IF(INDEX(Pedidos_DB!C:C,3+MATCH($D$2,Pedidos_DB!C4:C110,0)+1)<>$D$2,"",INDEX(Pedidos_DB!C:C,3+MATCH($D$2,Pedidos_DB!C4:C110,0)+1)),"") -> Setembro | D11: =IFERROR(IF(INDEX(Pedidos_DB!C:C,3+MATCH($D$2,Pedidos_DB!C4:C110,0)+1)<>$D$2,"",INDEX(Pedidos_DB!D:D,3+MATCH($D$2,Pedidos_DB!C4:C110,0)+1)),"") -> Salão Cabelos de Ouro | E11: =IFERROR(IF(INDEX(Pedidos_DB!C:C,3+MATCH($D$2,Pedidos_DB!C4:C110,0)+1)<>$D$2,"",INDEX(Pedidos_DB!E:E,3+MATCH($D$2,Pedidos_DB!C4:C110,0)+1)),"") -> Condicionador Nutritivo | F11: =IFERROR(IF(INDEX(Pedidos_DB!C:C,3+MATCH($D$2,Pedidos_DB!C4:C110,0)+1)<>$D$2,"",INDEX(Pedidos_DB!F:F,3+MATCH($D$2,Pedidos_DB!C4:C110,0)+1)),"") -> 20 | G11: =IFERROR(IF(INDEX(Pedidos_DB!C:C,3+MATCH($D$2,Pedidos_DB!C4:C110,0)+1)<>$D$2,"",INDEX(Pedidos_DB!G:G,3+MATCH($D$2,Pedidos_DB!C4:C110,0)+1)),"") -> 356 | H11: =IFERROR(IF(INDEX(Pedidos_DB!C:C,3+MATCH($D$2,Pedidos_DB!C4:C110,0)+1)<>$D$2,"",INDEX(Pedidos_DB!H:H,3+MATCH($D$2,Pedidos_DB!C4:C110,0)+1)),"") -> concluído | J11: Salão Glamour | L11: =SUMPRODUCT((Pedidos_DB!C4:C110=$D$2)*(Pedidos_DB!D4:D110=J11)*Pedidos_DB!G4:G110) -> 795.7
B12: =IFERROR(IF(INDEX(Pedidos_DB!C:C,3+MATCH($D$2,Pedidos_DB!C4:C110,0)+2)<>$D$2,"",INDEX(Pedidos_DB!B:B,3+MATCH($D$2,Pedidos_DB!C4:C110,0)+2)),"") -> 2024-09-08 | C12: =IFERROR(IF(INDEX(Pedidos_DB!C:C,3+MATCH($D$2,Pedidos_DB!C4:C110,0)+2)<>$D$2,"",INDEX(Pedidos_DB!C:C,3+MATCH($D$2,Pedidos_DB!C4:C110,0)+2)),"") -> Setembro | D12: =IFERROR(IF(INDEX(Pedidos_DB!C:C,3+MATCH($D$2,Pedidos_DB!C4:C110,0)+2)<>$D$2,"",INDEX(Pedidos_DB!D:D,3+MATCH($D$2,Pedidos_DB!C4:C110,0)+2)),"") -> Salão Beleza & Cia | E12: =IFERROR(IF(INDEX(Pedidos_DB!C:C,3+MATCH($D$2,Pedidos_DB!C4:C110,0)+2)<>$D$2,"",INDEX(Pedidos_DB!E:E,3+MATCH($D$2,Pedidos_DB!C4:C110,0)+2)),"") -> Ampola de Reparação | F12: =IFERROR(IF(INDEX(Pedidos_DB!C:C,3+MATCH($D$2,Pedidos_DB!C4:C110,0)+2)<>$D$2,"",INDEX(Pedidos_DB!F:F,3+MATCH($D$2,Pedidos_DB!C4:C110,0)+2)),"") -> 10 | G12: =IFERROR(IF(INDEX(Pedidos_DB!C:C,3+MATCH($D$2,Pedidos_DB!C4:C110,0)+2)<>$D$2,"",INDEX(Pedidos_DB!G:G,3+MATCH($D$2,Pedidos_DB!C4:C110,0)+2)),"") -> 125 | H12: =IFERROR(IF(INDEX(Pedidos_DB!C:C,3+MATCH($D$2,Pedidos_DB!C4:C110,0)+2)<>$D$2,"",INDEX(Pedidos_DB!H:H,3+MATCH($D$2,Pedidos_DB!C4:C110,0)+2)),"") -> concluído | J12: Salão Luxo Capilar | L12: =SUMPRODUCT((Pedidos_DB!C4:C110=$D$2)*(Pedidos_DB!D4:D110=J12)*Pedidos_DB!G4:G110) -> 685.2
B13: =IFERROR(IF(INDEX(Pedidos_DB!C:C,3+MATCH($D$2,Pedidos_DB!C4:C110,0)+3)<>$D$2,"",INDEX(Pedidos_DB!B:B,3+MATCH($D$2,Pedidos_DB!C4:C110,0)+3)),"") -> 2024-09-10 | C13: =IFERROR(IF(INDEX(Pedidos_DB!C:C,3+MATCH($D$2,Pedidos_DB!C4:C110,0)+3)<>$D$2,"",INDEX(Pedidos_DB!C:C,3+MATCH($D$2,Pedidos_DB!C4:C110,0)+3)),"") -> Setembro | D13: =IFERROR(IF(INDEX(Pedidos_DB!C:C,3+MATCH($D$2,Pedidos_DB!C4:C110,0)+3)<>$D$2,"",INDEX(Pedidos_DB!D:D,3+MATCH($D$2,Pedidos_DB!C4:C110,0)+3)),"") -> Salão Bella Cabelos | E13: =IFERROR(IF(INDEX(Pedidos_DB!C:C,3+MATCH($D$2,Pedidos_DB!C4:C110,0)+3)<>$D$2,"",INDEX(Pedidos_DB!E:E,3+MATCH($D$2,Pedidos_DB!C4:C110,0)+3)),"") -> Máscara de Hidratação | F13: =IFERROR(IF(INDEX(Pedidos_DB!C:C,3+MATCH($D$2,Pedidos_DB!C4:C110,0)+3)<>$D$2,"",INDEX(Pedidos_DB!F:F,3+MATCH($D$2,Pedidos_DB!C4:C110,0)+3)),"") -> 12 | G13: =IFERROR(IF(INDEX(Pedidos_DB!C:C,3+MATCH($D$2,Pedidos_DB!C4:C110,0)+3)<>$D$2,"",INDEX(Pedidos_DB!G:G,3+MATCH($D$2,Pedidos_DB!C4:C110,0)+3)),"") -> 420 | H13: =IFERROR(IF(INDEX(Pedidos_DB!C:C,3+MATCH($D$2,Pedidos_DB!C4:C110,0)+3)<>$D$2,"",INDEX(Pedidos_DB!H:H,3+MATCH($D$2,Pedidos_DB!C4:C110,0)+3)),"") -> concluído | J13: Salão Cabelos de Ouro | L13: =SUMPRODUCT((Pedidos_DB!C4:C110=$D$2)*(Pedidos_DB!D4:D110=J13)*Pedidos_DB!G4:G110) -> 754
B14: =IFERROR(IF(INDEX(Pedidos_DB!C:C,3+MATCH($D$2,Pedidos_DB!C4:C110,0)+4)<>$D$2,"",INDEX(Pedidos_DB!B:B,3+MATCH($D$2,Pedidos_DB!C4:C110,0)+4)),"") -> 2024-09-12 | C14: =IFERROR(IF(INDEX(Pedidos_DB!C:C,3+MATCH($D$2,Pedidos_DB!C4:C110,0)+4)<>$D$2,"",INDEX(Pedidos_DB!C:C,3+MATCH($D$2,Pedidos_DB!C4:C110,0)+4)),"") -> Setembro | D14: =IFERROR(IF(INDEX(Pedidos_DB!C:C,3+MATCH($D$2,Pedidos_DB!C4:C110,0)+4)<>$D$2,"",INDEX(Pedidos_DB!D:D,3+MATCH($D$2,Pedidos_DB!C4:C110,0)+4)),"") -> Salão Luxo Capilar | E14: =IFERROR(IF(INDEX(Pedidos_DB!C:C,3+MATCH($D$2,Pedidos_DB!C4:C110,0)+4)<>$D$2,"",INDEX(Pedidos_DB!E:E,3+MATCH($D$2,Pedidos_DB!C4:C110,0)+4)),"") -> Óleo de Rícino | F14: =IFERROR(IF(INDEX(Pedidos_DB!C:C,3+MATCH($D$2,Pedidos_DB!C4:C110,0)+4)<>$D$2,"",INDEX(Pedidos_DB!F:F,3+MATCH($D$2,Pedidos_DB!C4:C110,0)+4)),"") -> 18 | G14: =IFERROR(IF(INDEX(Pedidos_DB!C:C,3+MATCH($D$2,Pedidos_DB!C4:C110,0)+4)<>$D$2,"",INDEX(Pedidos_DB!G:G,3+MATCH($D$2,Pedidos_DB!C4:C110,0)+4)),"") -> 360 | H14: =IFERROR(IF(INDEX(Pedidos_DB!C:C,3+MATCH($D$2,Pedidos_DB!C4:C110,0)+4)<>$D$2,"",INDEX(Pedidos_DB!H:H,3+MATCH($D$2,Pedidos_DB!C4:C110,0)+4)),"") -> concluído | J14: Salão Bella Cabelos | L14: =SUMPRODUCT((Pedidos_DB!C4:C110=$D$2)*(Pedidos_DB!D4:D110=J14)*Pedidos_DB!G4:G110) -> 771
B15: =IFERROR(IF(INDEX(Pedidos_DB!C:C,3+MATCH($D$2,Pedidos_DB!C4:C110,0)+5)<>$D$2,"",INDEX(Pedidos_DB!B:B,3+MATCH($D$2,Pedidos_DB!C4:C110,0)+5)),"") -> 2024-09-15 | C15: =IFERROR(IF(INDEX(Pedidos_DB!C:C,3+MATCH($D$2,Pedidos_DB!C4:C110,0)+5)<>$D$2,"",INDEX(Pedidos_DB!C:C,3+MATCH($D$2,Pedidos_DB!C4:C110,0)+5)),"") -> Setembro | D15: =IFERROR(IF(INDEX(Pedidos_DB!C:C,3+MATCH($D$2,Pedidos_DB!C4:C110,0)+5)<>$D$2,"",INDEX(Pedidos_DB!D:D,3+MATCH($D$2,Pedidos_DB!C4:C110,0)+5)),"") -> Salão Glamour | E15: =IFERROR(IF(INDEX(Pedidos_DB!C:C,3+MATCH($D$2,Pedidos_DB!C4:C110,0)+5)<>$D$2,"",INDEX(Pedidos_DB!E:E,3+MATCH($D$2,Pedidos_DB!C4:C110,0)+5)),"") -> Creme de Pentear Hidratante | F15: =IFERROR(IF(INDEX(Pedidos_DB!C:C,3+MATCH($D$2,Pedidos_DB!C4:C110,0)+5)<>$D$2,"",INDEX(Pedidos_DB!F:F,3+MATCH($D$2,Pedidos_DB!C4:C110,0)+5)),"") -> 15 | G15: =IFERROR(IF(INDEX(Pedidos_DB!C:C,3+MATCH($D$2,Pedidos_DB!C4:C110,0)+5)<>$D$2,"",INDEX(Pedidos_DB!G:G,3+MATCH($D$2,Pedidos_DB!C4:C110,0)+5)),"") -> 273 | H15: =IFERROR(IF(INDEX(Pedidos_DB!C:C,3+MATCH($D$2,Pedidos_DB!C4:C110,0)+5)<>$D$2,"",INDEX(Pedidos_DB!H:H,3+MATCH($D$2,Pedidos_DB!C4:C110,0)+5)),"") -> concluído
B16: =IFERROR(IF(INDEX(Pedidos_DB!C:C,3+MATCH($D$2,Pedidos_DB!C4:C110,0)+6)<>$D$2,"",INDEX(Pedidos_DB!B:B,3+MATCH($D$2,Pedidos_DB!C4:C110,0)+6)),"") -> 2024-09-17 | C16: =IFERROR(IF(INDEX(Pedidos_DB!C:C,3+MATCH($D$2,Pedidos_DB!C4:C110,0)+6)<>$D$2,"",INDEX(Pedidos_DB!C:C,3+MATCH($D$2,Pedidos_DB!C4:C110,0)+6)),"") -> Setembro | D16: =IFERROR(IF(INDEX(Pedidos_DB!C:C,3+MATCH($D$2,Pedidos_DB!C4:C110,0)+6)<>$D$2,"",INDEX(Pedidos_DB!D:D,3+MATCH($D$2,Pedidos_DB!C4:C110,0)+6)),"") -> Salão Cabelos de Ouro | E16: =IFERROR(IF(INDEX(Pedidos_DB!C:C,3+MATCH($D$2,Pedidos_DB!C4:C110,0)+6)<>$D$2,"",INDEX(Pedidos_DB!E:E,3+MATCH($D$2,Pedidos_DB!C4:C110,0)+6)),"") -> Shampoo Detox | F16: =IFERROR(IF(INDEX(Pedidos_DB!C:C,3+MATCH($D$2,Pedidos_DB!C4:C110,0)+6)<>$D$2,"",INDEX(Pedidos_DB!F:F,3+MATCH($D$2,Pedidos_DB!C4:C110,0)+6)),"") -> 20 | G16: =IFERROR(IF(INDEX(Pedidos_DB!C:C,3+MATCH($D$2,Pedidos_DB!C4:C110,0)+6)<>$D$2,"",INDEX(Pedidos_DB!G:G,3+MATCH($D$2,Pedidos_DB!C4:C110,0)+6)),"") -> 398 | H16: =IFERROR(IF(INDEX(Pedidos_DB!C:C,3+MATCH($D$2,Pedidos_DB!C4:C110,0)+6)<>$D$2,"",INDEX(Pedidos_DB!H:H,3+MATCH($D$2,Pedidos_DB!C4:C110,0)+6)),"") -> concluído
B17: =IFERROR(IF(INDEX(Pedidos_DB!C:C,3+MATCH($D$2,Pedidos_DB!C4:C110,0)+7)<>$D$2,"",INDEX(Pedidos_DB!B:B,3+MATCH($D$2,Pedidos_DB!C4:C110,0)+7)),"") -> 2024-09-20 | C17: =IFERROR(IF(INDEX(Pedidos_DB!C:C,3+MATCH($D$2,Pedidos_DB!C4:C110,0)+7)<>$D$2,"",INDEX(Pedidos_DB!C:C,3+MATCH($D$2,Pedidos_DB!C4:C110,0)+7)),"") -> Setembro | D17: =IFERROR(IF(INDEX(Pedidos_DB!C:C,3+MATCH($D$2,Pedidos_DB!C4:C110,0)+7)<>$D$2,"",INDEX(Pedidos_DB!D:D,3+MATCH($D$2,Pedidos_DB!C4:C110,0)+7)),"") -> Salão Beleza & Cia | E17: =IFERROR(IF(INDEX(Pedidos_DB!C:C,3+MATCH($D$2,Pedidos_DB!C4:C110,0)+7)<>$D$2,"",INDEX(Pedidos_DB!E:E,3+MATCH($D$2,Pedidos_DB!C4:C110,0)+7)),"") -> Máscara de Nutrição Profunda | F17: =IFERROR(IF(INDEX(Pedidos_DB!C:C,3+MATCH($D$2,Pedidos_DB!C4:C110,0)+7)<>$D$2,"",INDEX(Pedidos_DB!F:F,3+MATCH($D$2,Pedidos_DB!C4:C110,0)+7)),"") -> 10 | G17: =IFERROR(IF(INDEX(Pedidos_DB!C:C,3+MATCH($D$2,Pedidos_DB!C4:C110,0)+7)<>$D$2,"",INDEX(Pedidos_DB!G:G,3+MATCH($D$2,Pedidos_DB!C4:C110,0)+7)),"") -> 420 | H17: =IFERROR(IF(INDEX(Pedidos_DB!C:C,3+MATCH($D$2,Pedidos_DB!C4:C110,0)+7)<>$D$2,"",INDEX(Pedidos_DB!H:H,3+MATCH($D$2,Pedidos_DB!C4:C110,0)+7)),"") -> concluído
B18: =IFERROR(IF(INDEX(Pedidos_DB!C:C,3+MATCH($D$2,Pedidos_DB!C4:C110,0)+8)<>$D$2,"",INDEX(Pedidos_DB!B:B,3+MATCH($D$2,Pedidos_DB!C4:C110,0)+8)),"") -> 2024-09-22 | C18: =IFERROR(IF(INDEX(Pedidos_DB!C:C,3+MATCH($D$2,Pedidos_DB!C4:C110,0)+8)<>$D$2,"",INDEX(Pedidos_DB!C:C,3+MATCH($D$2,Pedidos_DB!C4:C110,0)+8)),"") -> Setembro | D18: =IFERROR(IF(INDEX(Pedidos_DB!C:C,3+MATCH($D$2,Pedidos_DB!C4:C110,0)+8)<>$D$2,"",INDEX(Pedidos_DB!D:D,3+MATCH($D$2,Pedidos_DB!C4:C110,0)+8)),"") -> Salão Bella Cabelos | E18: =IFERROR(IF(INDEX(Pedidos_DB!C:C,3+MATCH($D$2,Pedidos_DB!C4:C110,0)+8)<>$D$2,"",INDEX(Pedidos_DB!E:E,3+MATCH($D$2,Pedidos_DB!C4:C110,0)+8)),"") -> Leave-in Nutritivo | F18: =IFERROR(IF(INDEX(Pedidos_DB!C:C,3+MATCH($D$2,Pedidos_DB!C4:C110,0)+8)<>$D$2,"",INDEX(Pedidos_DB!F:F,3+MATCH($D$2,Pedidos_DB!C4:C110,0)+8)),"") -> 15 | G18: =IFERROR(IF(INDEX(Pedidos_DB!C:C,3+MATCH($D$2,Pedidos_DB!C4:C110,0)+8)<>$D$2,"",INDEX(Pedidos_DB!G:G,3+MATCH($D$2,Pedidos_DB!C4:C110,0)+8)),"") -> 351 | H18: =IFERROR(IF(INDEX(Pedidos_DB!C:C,3+MATCH($D$2,Pedidos_DB!C4:C110,0)+8)<>$D$2,"",INDEX(Pedidos_DB!H:H,3+MATCH($D$2,Pedidos_DB!C4:C110,0)+8)),"") -> concluído
B19: =IFERROR(IF(INDEX(Pedidos_DB!C:C,3+MATCH($D$2,Pedidos_DB!C4:C110,0)+9)<>$D$2,"",INDEX(Pedidos_DB!B:B,3+MATCH($D$2,Pedidos_DB!C4:C110,0)+9)),"") -> 2024-09-25 | C19: =IFERROR(IF(INDEX(Pedidos_DB!C:C,3+MATCH($D$2,Pedidos_DB!C4:C110,0)+9)<>$D$2,"",INDEX(Pedidos_DB!C:C,3+MATCH($D$2,Pedidos_DB!C4:C110,0)+9)),"") -> Setembro | D19: =IFERROR(IF(INDEX(Pedidos_DB!C:C,3+MATCH($D$2,Pedidos_DB!C4:C110,0)+9)<>$D$2,"",INDEX(Pedidos_DB!D:D,3+MATCH($D$2,Pedidos_DB!C4:C110,0)+9)),"") -> Salão Luxo Capilar | E19: =IFERROR(IF(INDEX(Pedidos_DB!C:C,3+MATCH($D$2,Pedidos_DB!C4:C110,0)+9)<>$D$2,"",INDEX(Pedidos_DB!E:E,3+MATCH($D$2,Pedidos_DB!C4:C110,0)+9)),"") -> Condicionador Antifrizz | F19: =IFERROR(IF(INDEX(Pedidos_DB!C:C,3+MATCH($D$2,Pedidos_DB!C4:C110,0)+9)<>$D$2,"",INDEX(Pedidos_DB!F:F,3+MATCH($D$2,Pedidos_DB!C4:C110,0)+9)),"") -> 12 | G19: =IFERROR(IF(INDEX(Pedidos_DB!C:C,3+MATCH($D$2,Pedidos_DB!C4:C110,0)+9)<>$D$2,"",INDEX(Pedidos_DB!G:G,3+MATCH($D$2,Pedidos_DB!C4:C110,0)+9)),"") -> 325.2 | H19: =IFERROR(IF(INDEX(Pedidos_DB!C:C,3+MATCH($D$2,Pedidos_DB!C4:C110,0)+9)<>$D$2,"",INDEX(Pedidos_DB!H:H,3+MATCH($D$2,Pedidos_DB!C4:C110,0)+9)),"") -> concluído
B20: =IFERROR(IF(INDEX(Pedidos_DB!C:C,3+MATCH($D$2,Pedidos_DB!C4:C110,0)+10)<>$D$2,"",INDEX(Pedidos_DB!B:B,3+MATCH($D$2,Pedidos_DB!C4:C110,0)+10)),"") -> 2024-09-27 | C20: =IFERROR(IF(INDEX(Pedidos_DB!C:C,3+MATCH($D$2,Pedidos_DB!C4:C110,0)+10)<>$D$2,"",INDEX(Pedidos_DB!C:C,3+MATCH($D$2,Pedidos_DB!C4:C110,0)+10)),"") -> Setembro | D20: =IFERROR(IF(INDEX(Pedidos_DB!C:C,3+MATCH($D$2,Pedidos_DB!C4:C110,0)+10)<>$D$2,"",INDEX(Pedidos_DB!D:D,3+MATCH($D$2,Pedidos_DB!C4:C110,0)+10)),"") -> Salão Glamour | E20: =IFERROR(IF(INDEX(Pedidos_DB!C:C,3+MATCH($D$2,Pedidos_DB!C4:C110,0)+10)<>$D$2,"",INDEX(Pedidos_DB!E:E,3+MATCH($D$2,Pedidos_DB!C4:C110,0)+10)),"") -> Óleo de Argan | F20: =IFERROR(IF(INDEX(Pedidos_DB!C:C,3+MATCH($D$2,Pedidos_DB!C4:C110,0)+10)<>$D$2,"",INDEX(Pedidos_DB!F:F,3+MATCH($D$2,Pedidos_DB!C4:C110,0)+10)),"") -> 8 | G20: =IFERROR(IF(INDEX(Pedidos_DB!C:C,3+MATCH($D$2,Pedidos_DB!C4:C110,0)+10)<>$D$2,"",INDEX(Pedidos_DB!G:G,3+MATCH($D$2,Pedidos_DB!C4:C110,0)+10)),"") -> 239.2 | H20: =IFERROR(IF(INDEX(Pedidos_DB!C:C,3+MATCH($D$2,Pedidos_DB!C4:C110,0)+10)<>$D$2,"",INDEX(Pedidos_DB!H:H,3+MATCH($D$2,Pedidos_DB!C4:C110,0)+10)),"") -> concluído
B21: =IFERROR(IF(INDEX(Pedidos_DB!C:C,3+MATCH($D$2,Pedidos_DB!C4:C110,0)+11)<>$D$2,"",INDEX(Pedidos_DB!B:B,3+MATCH($D$2,Pedidos_DB!C4:C110,0)+11)),"") | C21: =IFERROR(IF(INDEX(Pedidos_DB!C:C,3+MATCH($D$2,Pedidos_DB!C4:C110,0)+11)<>$D$2,"",INDEX(Pedidos_DB!C:C,3+MATCH($D$2,Pedidos_DB!C4:C110,0)+11)),"") | D21: =IFERROR(IF(INDEX(Pedidos_DB!C:C,3+MATCH($D$2,Pedidos_DB!C4:C110,0)+11)<>$D$2,"",INDEX(Pedidos_DB!D:D,3+MATCH($D$2,Pedidos_DB!C4:C110,0)+11)),"") | E21: =IFERROR(IF(INDEX(Pedidos_DB!C:C,3+MATCH($D$2,Pedidos_DB!C4:C110,0)+11)<>$D$2,"",INDEX(Pedidos_DB!E:E,3+MATCH($D$2,Pedidos_DB!C4:C110,0)+11)),"") | F21: =IFERROR(IF(INDEX(Pedidos_DB!C:C,3+MATCH($D$2,Pedidos_DB!C4:C110,0)+11)<>$D$2,"",INDEX(Pedidos_DB!F:F,3+MATCH($D$2,Pedidos_DB!C4:C110,0)+11)),"") | G21: =IFERROR(IF(INDEX(Pedidos_DB!C:C,3+MATCH($D$2,Pedidos_DB!C4:C110,0)+11)<>$D$2,"",INDEX(Pedidos_DB!G:G,3+MATCH($D$2,Pedidos_DB!C4:C110,0)+11)),"") | H21: =IFERROR(IF(INDEX(Pedidos_DB!C:C,3+MATCH($D$2,Pedidos_DB!C4:C110,0)+11)<>$D$2,"",INDEX(Pedidos_DB!H:H,3+MATCH($D$2,Pedidos_DB!C4:C110,0)+11)),"")
B22: =IFERROR(IF(INDEX(Pedidos_DB!C:C,3+MATCH($D$2,Pedidos_DB!C4:C110,0)+12)<>$D$2,"",INDEX(Pedidos_DB!B:B,3+MATCH($D$2,Pedidos_DB!C4:C110,0)+12)),"") | C22: =IFERROR(IF(INDEX(Pedidos_DB!C:C,3+MATCH($D$2,Pedidos_DB!C4:C110,0)+12)<>$D$2,"",INDEX(Pedidos_DB!C:C,3+MATCH($D$2,Pedidos_DB!C4:C110,0)+12)),"") | D22: =IFERROR(IF(INDEX(Pedidos_DB!C:C,3+MATCH($D$2,Pedidos_DB!C4:C110,0)+12)<>$D$2,"",INDEX(Pedidos_DB!D:D,3+MATCH($D$2,Pedidos_DB!C4:C110,0)+12)),"") | E22: =IFERROR(IF(INDEX(Pedidos_DB!C:C,3+MATCH($D$2,Pedidos_DB!C4:C110,0)+12)<>$D$2,"",INDEX(Pedidos_DB!E:E,3+MATCH($D$2,Pedidos_DB!C4:C110,0)+12)),"") | F22: =IFERROR(IF(INDEX(Pedidos_DB!C:C,3+MATCH($D$2,Pedidos_DB!C4:C110,0)+12)<>$D$2,"",INDEX(Pedidos_DB!F:F,3+MATCH($D$2,Pedidos_DB!C4:C110,0)+12)),"") | G22: =IFERROR(IF(INDEX(Pedidos_DB!C:C,3+MATCH($D$2,Pedidos_DB!C4:C110,0)+12)<>$D$2,"",INDEX(Pedidos_DB!G:G,3+MATCH($D$2,Pedidos_DB!C4:C110,0)+12)),"") | H22: =IFERROR(IF(INDEX(Pedidos_DB!C:C,3+MATCH($D$2,Pedidos_DB!C4:C110,0)+12)<>$D$2,"",INDEX(Pedidos_DB!H:H,3+MATCH($D$2,Pedidos_DB!C4:C110,0)+12)),"")
B23: =IFERROR(IF(INDEX(Pedidos_DB!C:C,3+MATCH($D$2,Pedidos_DB!C4:C110,0)+13)<>$D$2,"",INDEX(Pedidos_DB!B:B,3+MATCH($D$2,Pedidos_DB!C4:C110,0)+13)),"") | C23: =IFERROR(IF(INDEX(Pedidos_DB!C:C,3+MATCH($D$2,Pedidos_DB!C4:C110,0)+13)<>$D$2,"",INDEX(Pedidos_DB!C:C,3+MATCH($D$2,Pedidos_DB!C4:C110,0)+13)),"") | D23: =IFERROR(IF(INDEX(Pedidos_DB!C:C,3+MATCH($D$2,Pedidos_DB!C4:C110,0)+13)<>$D$2,"",INDEX(Pedidos_DB!D:D,3+MATCH($D$2,Pedidos_DB!C4:C110,0)+13)),"") | E23: =IFERROR(IF(INDEX(Pedidos_DB!C:C,3+MATCH($D$2,Pedidos_DB!C4:C110,0)+13)<>$D$2,"",INDEX(Pedidos_DB!E:E,3+MATCH($D$2,Pedidos_DB!C4:C110,0)+13)),"") | F23: =IFERROR(IF(INDEX(Pedidos_DB!C:C,3+MATCH($D$2,Pedidos_DB!C4:C110,0)+13)<>$D$2,"",INDEX(Pedidos_DB!F:F,3+MATCH($D$2,Pedidos_DB!C4:C110,0)+13)),"") | G23: =IFERROR(IF(INDEX(Pedidos_DB!C:C,3+MATCH($D$2,Pedidos_DB!C4:C110,0)+13)<>$D$2,"",INDEX(Pedidos_DB!G:G,3+MATCH($D$2,Pedidos_DB!C4:C110,0)+13)),"") | H23: =IFERROR(IF(INDEX(Pedidos_DB!C:C,3+MATCH($D$2,Pedidos_DB!C4:C110,0)+13)<>$D$2,"",INDEX(Pedidos_DB!H:H,3+MATCH($D$2,Pedidos_DB!C4:C110,0)+13)),"")
B24: =IFERROR(IF(INDEX(Pedidos_DB!C:C,3+MATCH($D$2,Pedidos_DB!C4:C110,0)+14)<>$D$2,"",INDEX(Pedidos_DB!B:B,3+MATCH($D$2,Pedidos_DB!C4:C110,0)+14)),"") | C24: =IFERROR(IF(INDEX(Pedidos_DB!C:C,3+MATCH($D$2,Pedidos_DB!C4:C110,0)+14)<>$D$2,"",INDEX(Pedidos_DB!C:C,3+MATCH($D$2,Pedidos_DB!C4:C110,0)+14)),"") | D24: =IFERROR(IF(INDEX(Pedidos_DB!C:C,3+MATCH($D$2,Pedidos_DB!C4:C110,0)+14)<>$D$2,"",INDEX(Pedidos_DB!D:D,3+MATCH($D$2,Pedidos_DB!C4:C110,0)+14)),"") | E24: =IFERROR(IF(INDEX(Pedidos_DB!C:C,3+MATCH($D$2,Pedidos_DB!C4:C110,0)+14)<>$D$2,"",INDEX(Pedidos_DB!E:E,3+MATCH($D$2,Pedidos_DB!C4:C110,0)+14)),"") | F24: =IFERROR(IF(INDEX(Pedidos_DB!C:C,3+MATCH($D$2,Pedidos_DB!C4:C110,0)+14)<>$D$2,"",INDEX(Pedidos_DB!F:F,3+MATCH($D$2,Pedidos_DB!C4:C110,0)+14)),"") | G24: =IFERROR(IF(INDEX(Pedidos_DB!C:C,3+MATCH($D$2,Pedidos_DB!C4:C110,0)+14)<>$D$2,"",INDEX(Pedidos_DB!G:G,3+MATCH($D$2,Pedidos_DB!C4:C110,0)+14)),"") | H24: =IFERROR(IF(INDEX(Pedidos_DB!C:C,3+MATCH($D$2,Pedidos_DB!C4:C110,0)+14)<>$D$2,"",INDEX(Pedidos_DB!H:H,3+MATCH($D$2,Pedidos_DB!C4:C110,0)+14)),"")
B25: =IFERROR(IF(INDEX(Pedidos_DB!C:C,3+MATCH($D$2,Pedidos_DB!C4:C110,0)+15)<>$D$2,"",INDEX(Pedidos_DB!B:B,3+MATCH($D$2,Pedidos_DB!C4:C110,0)+15)),"") | C25: =IFERROR(IF(INDEX(Pedidos_DB!C:C,3+MATCH($D$2,Pedidos_DB!C4:C110,0)+15)<>$D$2,"",INDEX(Pedidos_DB!C:C,3+MATCH($D$2,Pedidos_DB!C4:C110,0)+15)),"") | D25: =IFERROR(IF(INDEX(Pedidos_DB!C:C,3+MATCH($D$2,Pedidos_DB!C4:C110,0)+15)<>$D$2,"",INDEX(Pedidos_DB!D:D,3+MATCH($D$2,Pedidos_DB!C4:C110,0)+15)),"") | E25: =IFERROR(IF(INDEX(Pedidos_DB!C:C,3+MATCH($D$2,Pedidos_DB!C4:C110,0)+15)<>$D$2,"",INDEX(Pedidos_DB!E:E,3+MATCH($D$2,Pedidos_DB!C4:C110,0)+15)),"") | F25: =IFERROR(IF(INDEX(Pedidos_DB!C:C,3+MATCH($D$2,Pedidos_DB!C4:C110,0)+15)<>$D$2,"",INDEX(Pedidos_DB!F:F,3+MATCH($D$2,Pedidos_DB!C4:C110,0)+15)),"") | G25: =IFERROR(IF(INDEX(Pedidos_DB!C:C,3+MATCH($D$2,Pedidos_DB!C4:C110,0)+15)<>$D$2,"",INDEX(Pedidos_DB!G:G,3+MATCH($D$2,Pedidos_DB!C4:C110,0)+15)),"") | H25: =IFERROR(IF(INDEX(Pedidos_DB!C:C,3+MATCH($D$2,Pedidos_DB!C4:C110,0)+15)<>$D$2,"",INDEX(Pedidos_DB!H:H,3+MATCH($D$2,Pedidos_DB!C4:C110,0)+15)),"")
B26: =IFERROR(IF(INDEX(Pedidos_DB!C:C,3+MATCH($D$2,Pedidos_DB!C4:C110,0)+16)<>$D$2,"",INDEX(Pedidos_DB!B:B,3+MATCH($D$2,Pedidos_DB!C4:C110,0)+16)),"") | C26: =IFERROR(IF(INDEX(Pedidos_DB!C:C,3+MATCH($D$2,Pedidos_DB!C4:C110,0)+16)<>$D$2,"",INDEX(Pedidos_DB!C:C,3+MATCH($D$2,Pedidos_DB!C4:C110,0)+16)),"") | D26: =IFERROR(IF(INDEX(Pedidos_DB!C:C,3+MATCH($D$2,Pedidos_DB!C4:C110,0)+16)<>$D$2,"",INDEX(Pedidos_DB!D:D,3+MATCH($D$2,Pedidos_DB!C4:C110,0)+16)),"") | E26: =IFERROR(IF(INDEX(Pedidos_DB!C:C,3+MATCH($D$2,Pedidos_DB!C4:C110,0)+16)<>$D$2,"",INDEX(Pedidos_DB!E:E,3+MATCH($D$2,Pedidos_DB!C4:C110,0)+16)),"") | F26: =IFERROR(IF(INDEX(Pedidos_DB!C:C,3+MATCH($D$2,Pedidos_DB!C4:C110,0)+16)<>$D$2,"",INDEX(Pedidos_DB!F:F,3+MATCH($D$2,Pedidos_DB!C4:C110,0)+16)),"") | G26: =IFERROR(IF(INDEX(Pedidos_DB!C:C,3+MATCH($D$2,Pedidos_DB!C4:C110,0)+16)<>$D$2,"",INDEX(Pedidos_DB!G:G,3+MATCH($D$2,Pedidos_DB!C4:C110,0)+16)),"") | H26: =IFERROR(IF(INDEX(Pedidos_DB!C:C,3+MATCH($D$2,Pedidos_DB!C4:C110,0)+16)<>$D$2,"",INDEX(Pedidos_DB!H:H,3+MATCH($D$2,Pedidos_DB!C4:C110,0)+16)),"")
B27: =IFERROR(IF(INDEX(Pedidos_DB!C:C,3+MATCH($D$2,Pedidos_DB!C4:C110,0)+17)<>$D$2,"",INDEX(Pedidos_DB!B:B,3+MATCH($D$2,Pedidos_DB!C4:C110,0)+17)),"") | C27: =IFERROR(IF(INDEX(Pedidos_DB!C:C,3+MATCH($D$2,Pedidos_DB!C4:C110,0)+17)<>$D$2,"",INDEX(Pedidos_DB!C:C,3+MATCH($D$2,Pedidos_DB!C4:C110,0)+17)),"") | D27: =IFERROR(IF(INDEX(Pedidos_DB!C:C,3+MATCH($D$2,Pedidos_DB!C4:C110,0)+17)<>$D$2,"",INDEX(Pedidos_DB!D:D,3+MATCH($D$2,Pedidos_DB!C4:C110,0)+17)),"") | E27: =IFERROR(IF(INDEX(Pedidos_DB!C:C,3+MATCH($D$2,Pedidos_DB!C4:C110,0)+17)<>$D$2,"",INDEX(Pedidos_DB!E:E,3+MATCH($D$2,Pedidos_DB!C4:C110,0)+17)),"") | F27: =IFERROR(IF(INDEX(Pedidos_DB!C:C,3+MATCH($D$2,Pedidos_DB!C4:C110,0)+17)<>$D$2,"",INDEX(Pedidos_DB!F:F,3+MATCH($D$2,Pedidos_DB!C4:C110,0)+17)),"") | G27: =IFERROR(IF(INDEX(Pedidos_DB!C:C,3+MATCH($D$2,Pedidos_DB!C4:C110,0)+17)<>$D$2,"",INDEX(Pedidos_DB!G:G,3+MATCH($D$2,Pedidos_DB!C4:C110,0)+17)),"") | H27: =IFERROR(IF(INDEX(Pedidos_DB!C:C,3+MATCH($D$2,Pedidos_DB!C4:C110,0)+17)<>$D$2,"",INDEX(Pedidos_DB!H:H,3+MATCH($D$2,Pedidos_DB!C4:C110,0)+17)),"")
B28: =IFERROR(IF(INDEX(Pedidos_DB!C:C,3+MATCH($D$2,Pedidos_DB!C4:C110,0)+18)<>$D$2,"",INDEX(Pedidos_DB!B:B,3+MATCH($D$2,Pedidos_DB!C4:C110,0)+18)),"") | C28: =IFERROR(IF(INDEX(Pedidos_DB!C:C,3+MATCH($D$2,Pedidos_DB!C4:C110,0)+18)<>$D$2,"",INDEX(Pedidos_DB!C:C,3+MATCH($D$2,Pedidos_DB!C4:C110,0)+18)),"") | D28: =IFERROR(IF(INDEX(Pedidos_DB!C:C,3+MATCH($D$2,Pedidos_DB!C4:C110,0)+18)<>$D$2,"",INDEX(Pedidos_DB!D:D,3+MATCH($D$2,Pedidos_DB!C4:C110,0)+18)),"") | E28: =IFERROR(IF(INDEX(Pedidos_DB!C:C,3+MATCH($D$2,Pedidos_DB!C4:C110,0)+18)<>$D$2,"",INDEX(Pedidos_DB!E:E,3+MATCH($D$2,Pedidos_DB!C4:C110,0)+18)),"") | F28: =IFERROR(IF(INDEX(Pedidos_DB!C:C,3+MATCH($D$2,Pedidos_DB!C4:C110,0)+18)<>$D$2,"",INDEX(Pedidos_DB!F:F,3+MATCH($D$2,Pedidos_DB!C4:C110,0)+18)),"") | G28: =IFERROR(IF(INDEX(Pedidos_DB!C:C,3+MATCH($D$2,Pedidos_DB!C4:C110,0)+18)<>$D$2,"",INDEX(Pedidos_DB!G:G,3+MATCH($D$2,Pedidos_DB!C4:C110,0)+18)),"") | H28: =IFERROR(IF(INDEX(Pedidos_DB!C:C,3+MATCH($D$2,Pedidos_DB!C4:C110,0)+18)<>$D$2,"",INDEX(Pedidos_DB!H:H,3+MATCH($D$2,Pedidos_DB!C4:C110,0)+18)),"")
B29: =IFERROR(IF(INDEX(Pedidos_DB!C:C,3+MATCH($D$2,Pedidos_DB!C4:C110,0)+19)<>$D$2,"",INDEX(Pedidos_DB!B:B,3+MATCH($D$2,Pedidos_DB!C4:C110,0)+19)),"") | C29: =IFERROR(IF(INDEX(Pedidos_DB!C:C,3+MATCH($D$2,Pedidos_DB!C4:C110,0)+19)<>$D$2,"",INDEX(Pedidos_DB!C:C,3+MATCH($D$2,Pedidos_DB!C4:C110,0)+19)),"") | D29: =IFERROR(IF(INDEX(Pedidos_DB!C:C,3+MATCH($D$2,Pedidos_DB!C4:C110,0)+19)<>$D$2,"",INDEX(Pedidos_DB!D:D,3+MATCH($D$2,Pedidos_DB!C4:C110,0)+19)),"") | E29: =IFERROR(IF(INDEX(Pedidos_DB!C:C,3+MATCH($D$2,Pedidos_DB!C4:C110,0)+19)<>$D$2,"",INDEX(Pedidos_DB!E:E,3+MATCH($D$2,Pedidos_DB!C4:C110,0)+19)),"") | F29: =IFERROR(IF(INDEX(Pedidos_DB!C:C,3+MATCH($D$2,Pedidos_DB!C4:C110,0)+19)<>$D$2,"",INDEX(Pedidos_DB!F:F,3+MATCH($D$2,Pedidos_DB!C4:C110,0)+19)),"") | G29: =IFERROR(IF(INDEX(Pedidos_DB!C:C,3+MATCH($D$2,Pedidos_DB!C4:C110,0)+19)<>$D$2,"",INDEX(Pedidos_DB!G:G,3+MATCH($D$2,Pedidos_DB!C4:C110,0)+19)),"") | H29: =IFERROR(IF(INDEX(Pedidos_DB!C:C,3+MATCH($D$2,Pedidos_DB!C4:C110,0)+19)<>$D$2,"",INDEX(Pedidos_DB!H:H,3+MATCH($D$2,Pedidos_DB!C4:C110,0)+19)),"")
B30: =IFERROR(IF(INDEX(Pedidos_DB!C:C,3+MATCH($D$2,Pedidos_DB!C4:C110,0)+20)<>$D$2,"",INDEX(Pedidos_DB!B:B,3+MATCH($D$2,Pedidos_DB!C4:C110,0)+20)),"") | C30: =IFERROR(IF(INDEX(Pedidos_DB!C:C,3+MATCH($D$2,Pedidos_DB!C4:C110,0)+20)<>$D$2,"",INDEX(Pedidos_DB!C:C,3+MATCH($D$2,Pedidos_DB!C4:C110,0)+20)),"") | D30: =IFERROR(IF(INDEX(Pedidos_DB!C:C,3+MATCH($D$2,Pedidos_DB!C4:C110,0)+20)<>$D$2,"",INDEX(Pedidos_DB!D:D,3+MATCH($D$2,Pedidos_DB!C4:C110,0)+20)),"") | E30: =IFERROR(IF(INDEX(Pedidos_DB!C:C,3+MATCH($D$2,Pedidos_DB!C4:C110,0)+20)<>$D$2,"",INDEX(Pedidos_DB!E:E,3+MATCH($D$2,Pedidos_DB!C4:C110,0)+20)),"") | F30: =IFERROR(IF(INDEX(Pedidos_DB!C:C,3+MATCH($D$2,Pedidos_DB!C4:C110,0)+20)<>$D$2,"",INDEX(Pedidos_DB!F:F,3+MATCH($D$2,Pedidos_DB!C4:C110,0)+20)),"") | G30: =IFERROR(IF(INDEX(Pedidos_DB!C:C,3+MATCH($D$2,Pedidos_DB!C4:C110,0)+20)<>$D$2,"",INDEX(Pedidos_DB!G:G,3+MATCH($D$2,Pedidos_DB!C4:C110,0)+20)),"") | H30: =IFERROR(IF(INDEX(Pedidos_DB!C:C,3+MATCH($D$2,Pedidos_DB!C4:C110,0)+20)<>$D$2,"",INDEX(Pedidos_DB!H:H,3+MATCH($D$2,Pedidos_DB!C4:C110,0)+20)),"")
B31: =IFERROR(IF(INDEX(Pedidos_DB!C:C,3+MATCH($D$2,Pedidos_DB!C4:C110,0)+21)<>$D$2,"",INDEX(Pedidos_DB!B:B,3+MATCH($D$2,Pedidos_DB!C4:C110,0)+21)),"") | C31: =IFERROR(IF(INDEX(Pedidos_DB!C:C,3+MATCH($D$2,Pedidos_DB!C4:C110,0)+21)<>$D$2,"",INDEX(Pedidos_DB!C:C,3+MATCH($D$2,Pedidos_DB!C4:C110,0)+21)),"") | D31: =IFERROR(IF(INDEX(Pedidos_DB!C:C,3+MATCH($D$2,Pedidos_DB!C4:C110,0)+21)<>$D$2,"",INDEX(Pedidos_DB!D:D,3+MATCH($D$2,Pedidos_DB!C4:C110,0)+21)),"") | E31: =IFERROR(IF(INDEX(Pedidos_DB!C:C,3+MATCH($D$2,Pedidos_DB!C4:C110,0)+21)<>$D$2,"",INDEX(Pedidos_DB!E:E,3+MATCH($D$2,Pedidos_DB!C4:C110,0)+21)),"") | F31: =IFERROR(IF(INDEX(Pedidos_DB!C:C,3+MATCH($D$2,Pedidos_DB!C4:C110,0)+21)<>$D$2,"",INDEX(Pedidos_DB!F:F,3+MATCH($D$2,Pedidos_DB!C4:C110,0)+21)),"") | G31: =IFERROR(IF(INDEX(Pedidos_DB!C:C,3+MATCH($D$2,Pedidos_DB!C4:C110,0)+21)<>$D$2,"",INDEX(Pedidos_DB!G:G,3+MATCH($D$2,Pedidos_DB!C4:C110,0)+21)),"") | H31: =IFERROR(IF(INDEX(Pedidos_DB!C:C,3+MATCH($D$2,Pedidos_DB!C4:C110,0)+21)<>$D$2,"",INDEX(Pedidos_DB!H:H,3+MATCH($D$2,Pedidos_DB!C4:C110,0)+21)),"")
B32: =IFERROR(IF(INDEX(Pedidos_DB!C:C,3+MATCH($D$2,Pedidos_DB!C4:C110,0)+22)<>$D$2,"",INDEX(Pedidos_DB!B:B,3+MATCH($D$2,Pedidos_DB!C4:C110,0)+22)),"") | C32: =IFERROR(IF(INDEX(Pedidos_DB!C:C,3+MATCH($D$2,Pedidos_DB!C4:C110,0)+22)<>$D$2,"",INDEX(Pedidos_DB!C:C,3+MATCH($D$2,Pedidos_DB!C4:C110,0)+22)),"") | D32: =IFERROR(IF(INDEX(Pedidos_DB!C:C,3+MATCH($D$2,Pedidos_DB!C4:C110,0)+22)<>$D$2,"",INDEX(Pedidos_DB!D:D,3+MATCH($D$2,Pedidos_DB!C4:C110,0)+22)),"") | E32: =IFERROR(IF(INDEX(Pedidos_DB!C:C,3+MATCH($D$2,Pedidos_DB!C4:C110,0)+22)<>$D$2,"",INDEX(Pedidos_DB!E:E,3+MATCH($D$2,Pedidos_DB!C4:C110,0)+22)),"") | F32: =IFERROR(IF(INDEX(Pedidos_DB!C:C,3+MATCH($D$2,Pedidos_DB!C4:C110,0)+22)<>$D$2,"",INDEX(Pedidos_DB!F:F,3+MATCH($D$2,Pedidos_DB!C4:C110,0)+22)),"") | G32: =IFERROR(IF(INDEX(Pedidos_DB!C:C,3+MATCH($D$2,Pedidos_DB!C4:C110,0)+22)<>$D$2,"",INDEX(Pedidos_DB!G:G,3+MATCH($D$2,Pedidos_DB!C4:C110,0)+22)),"") | H32: =IFERROR(IF(INDEX(Pedidos_DB!C:C,3+MATCH($D$2,Pedidos_DB!C4:C110,0)+22)<>$D$2,"",INDEX(Pedidos_DB!H:H,3+MATCH($D$2,Pedidos_DB!C4:C110,0)+22)),"")
B33: =IFERROR(IF(INDEX(Pedidos_DB!C:C,3+MATCH($D$2,Pedidos_DB!C4:C110,0)+23)<>$D$2,"",INDEX(Pedidos_DB!B:B,3+MATCH($D$2,Pedidos_DB!C4:C110,0)+23)),"") | C33: =IFERROR(IF(INDEX(Pedidos_DB!C:C,3+MATCH($D$2,Pedidos_DB!C4:C110,0)+23)<>$D$2,"",INDEX(Pedidos_DB!C:C,3+MATCH($D$2,Pedidos_DB!C4:C110,0)+23)),"") | D33: =IFERROR(IF(INDEX(Pedidos_DB!C:C,3+MATCH($D$2,Pedidos_DB!C4:C110,0)+23)<>$D$2,"",INDEX(Pedidos_DB!D:D,3+MATCH($D$2,Pedidos_DB!C4:C110,0)+23)),"") | E33: =IFERROR(IF(INDEX(Pedidos_DB!C:C,3+MATCH($D$2,Pedidos_DB!C4:C110,0)+23)<>$D$2,"",INDEX(Pedidos_DB!E:E,3+MATCH($D$2,Pedidos_DB!C4:C110,0)+23)),"") | F33: =IFERROR(IF(INDEX(Pedidos_DB!C:C,3+MATCH($D$2,Pedidos_DB!C4:C110,0)+23)<>$D$2,"",INDEX(Pedidos_DB!F:F,3+MATCH($D$2,Pedidos_DB!C4:C110,0)+23)),"") | G33: =IFERROR(IF(INDEX(Pedidos_DB!C:C,3+MATCH($D$2,Pedidos_DB!C4:C110,0)+23)<>$D$2,"",INDEX(Pedidos_DB!G:G,3+MATCH($D$2,Pedidos_DB!C4:C110,0)+23)),"") | H33: =IFERROR(IF(INDEX(Pedidos_DB!C:C,3+MATCH($D$2,Pedidos_DB!C4:C110,0)+23)<>$D$2,"",INDEX(Pedidos_DB!H:H,3+MATCH($D$2,Pedidos_DB!C4:C110,0)+23)),"")
B34: =IFERROR(IF(INDEX(Pedidos_DB!C:C,3+MATCH($D$2,Pedidos_DB!C4:C110,0)+24)<>$D$2,"",INDEX(Pedidos_DB!B:B,3+MATCH($D$2,Pedidos_DB!C4:C110,0)+24)),"") | C34: =IFERROR(IF(INDEX(Pedidos_DB!C:C,3+MATCH($D$2,Pedidos_DB!C4:C110,0)+24)<>$D$2,"",INDEX(Pedidos_DB!C:C,3+MATCH($D$2,Pedidos_DB!C4:C110,0)+24)),"") | D34: =IFERROR(IF(INDEX(Pedidos_DB!C:C,3+MATCH($D$2,Pedidos_DB!C4:C110,0)+24)<>$D$2,"",INDEX(Pedidos_DB!D:D,3+MATCH($D$2,Pedidos_DB!C4:C110,0)+24)),"") | E34: =IFERROR(IF(INDEX(Pedidos_DB!C:C,3+MATCH($D$2,Pedidos_DB!C4:C110,0)+24)<>$D$2,"",INDEX(Pedidos_DB!E:E,3+MATCH($D$2,Pedidos_DB!C4:C110,0)+24)),"") | F34: =IFERROR(IF(INDEX(Pedidos_DB!C:C,3+MATCH($D$2,Pedidos_DB!C4:C110,0)+24)<>$D$2,"",INDEX(Pedidos_DB!F:F,3+MATCH($D$2,Pedidos_DB!C4:C110,0)+24)),"") | G34: =IFERROR(IF(INDEX(Pedidos_DB!C:C,3+MATCH($D$2,Pedidos_DB!C4:C110,0)+24)<>$D$2,"",INDEX(Pedidos_DB!G:G,3+MATCH($D$2,Pedidos_DB!C4:C110,0)+24)),"") | H34: =IFERROR(IF(INDEX(Pedidos_DB!C:C,3+MATCH($D$2,Pedidos_DB!C4:C110,0)+24)<>$D$2,"",INDEX(Pedidos_DB!H:H,3+MATCH($D$2,Pedidos_DB!C4:C110,0)+24)),"")

Sheet Despesas
B1: 💸 CONTROLE DE DESPESAS
B2: 📅 Filtro de Mês: | D2: Outubro | G2: ⬅ Selecione o mês para atualizar
B4: 💸 Total Despesas | E4: 🧾 Nº Compras | H4: 📦 Maior Compra | J4: 📊 Média
B5: =SUMIF(Despesas_DB!C4:C99,$D$2,Despesas_DB!H4:H99) -> 3890 | E5: =COUNTIF(Despesas_DB!C4:C99,$D$2) -> 17 | H5: =IFERROR(_xludf.maxifs(Despesas_DB!H4:H99,Despesas_DB!C4:C99,$D$2),0) -> 0 | J5: =IFERROR(B5/D5,0) -> 0
B8: 📋 Compras do Mês Selecionado | I8: 📊 Por Categoria
B9: Data | C9: Descrição | D9: Produto | E9: Custo Unit. | F9: Qtd | G9: Total (R$) | I9: Categoria | J9: Total (R$) | K9: %
B10: =IFERROR(IF(INDEX(Despesas_DB!C:C,3+MATCH($D$2,Despesas_DB!C4:C99,0)+0)<>$D$2,"",INDEX(Despesas_DB!B:B,3+MATCH($D$2,Despesas_DB!C4:C99,0)+0)),"") -> 2024-10-01 | C10: =IFERROR(IF(INDEX(Despesas_DB!C:C,3+MATCH($D$2,Despesas_DB!C4:C99,0)+0)<>$D$2,"",INDEX(Despesas_DB!D:D,3+MATCH($D$2,Despesas_DB!C4:C99,0)+0)),"") -> Compra de Óleo | D10: =IFERROR(IF(INDEX(Despesas_DB!C:C,3+MATCH($D$2,Despesas_DB!C4:C99,0)+0)<>$D$2,"",INDEX(Despesas_DB!E:E,3+MATCH($D$2,Despesas_DB!C4:C99,0)+0)),"") -> Óleo de Rícino | E10: =IFERROR(IF(INDEX(Despesas_DB!C:C,3+MATCH($D$2,Despesas_DB!C4:C99,0)+0)<>$D$2,"",INDEX(Despesas_DB!F:F,3+MATCH($D$2,Despesas_DB!C4:C99,0)+0)),"") -> 12 | F10: =IFERROR(IF(INDEX(Despesas_DB!C:C,3+MATCH($D$2,Despesas_DB!C4:C99,0)+0)<>$D$2,"",INDEX(Despesas_DB!G:G,3+MATCH($D$2,Despesas_DB!C4:C99,0)+0)),"") -> 30 | G10: =IFERROR(IF(INDEX(Despesas_DB!C:C,3+MATCH($D$2,Despesas_DB!C4:C99,0)+0)<>$D$2,"",INDEX(Despesas_DB!H:H,3+MATCH($D$2,Despesas_DB!C4:C99,0)+0)),"") -> 360 | I10: Shampoo | J10: =SUMPRODUCT((Despesas_DB!C4:C99=$D$2)*(ISNUMBER(SEARCH(I10,Despesas_DB!E4:E99))*Despesas_DB!H4:H99)) -> 720 | K10: =IFERROR(J10/B5,0) -> 0.18508997
B11: =IFERROR(IF(INDEX(Despesas_DB!C:C,3+MATCH($D$2,Despesas_DB!C4:C99,0)+1)<>$D$2,"",INDEX(Despesas_DB!B:B,3+MATCH($D$2,Despesas_DB!C4:C99,0)+1)),"") -> 2024-10-02 | C11: =IFERROR(IF(INDEX(Despesas_DB!C:C,3+MATCH($D$2,Despesas_DB!C4:C99,0)+1)<>$D$2,"",INDEX(Despesas_DB!D:D,3+MATCH($D$2,Despesas_DB!C4:C99,0)+1)),"") -> Compra de Creme de Pentear | D11: =IFERROR(IF(INDEX(Despesas_DB!C:C,3+MATCH($D$2,Despesas_DB!C4:C99,0)+1)<>$D$2,"",INDEX(Despesas_DB!E:E,3+MATCH($D$2,Despesas_DB!C4:C99,0)+1)),"") -> Creme de Pentear Antifrizz | E11: =IFERROR(IF(INDEX(Despesas_DB!C:C,3+MATCH($D$2,Despesas_DB!C4:C99,0)+1)<>$D$2,"",INDEX(Despesas_DB!F:F,3+MATCH($D$2,Despesas_DB!C4:C99,0)+1)),"") -> 10 | F11: =IFERROR(IF(INDEX(Despesas_DB!C:C,3+MATCH($D$2,Despesas_DB!C4:C99,0)+1)<>$D$2,"",INDEX(Despesas_DB!G:G,3+MATCH($D$2,Despesas_DB!C4:C99,0)+1)),"") -> 20 | G11: =IFERROR(IF(INDEX(Despesas_DB!C:C,3+MATCH($D$2,Despesas_DB!C4:C99,0)+1)<>$D$2,"",INDEX(Despesas_DB!H:H,3+MATCH($D$2,Despesas_DB!C4:C99,0)+1)),"") -> 200 | I11: Condicionador | J11: =SUMPRODUCT((Despesas_DB!C4:C99=$D$2)*(ISNUMBER(SEARCH(I11,Despesas_DB!E4:E99))*Despesas_DB!H4:H99)) -> 670 | K11: =IFERROR(J11/B5,0) -> 0.1722365
B12: =IFERROR(IF(INDEX(Despesas_DB!C:C,3+MATCH($D$2,Despesas_DB!C4:C99,0)+2)<>$D$2,"",INDEX(Despesas_DB!B:B,3+MATCH($D$2,Despesas_DB!C4:C99,0)+2)),"") -> 2024-10-03 | C12: =IFERROR(IF(INDEX(Despesas_DB!C:C,3+MATCH($D$2,Despesas_DB!C4:C99,0)+2)<>$D$2,"",INDEX(Despesas_DB!D:D,3+MATCH($D$2,Despesas_DB!C4:C99,0)+2)),"") -> Compra de Creme de Pentear | D12: =IFERROR(IF(INDEX(Despesas_DB!C:C,3+MATCH($D$2,Despesas_DB!C4:C99,0)+2)<>$D$2,"",INDEX(Despesas_DB!E:E,3+MATCH($D$2,Despesas_DB!C4:C99,0)+2)),"") -> Creme de Pentear Hidratante | E12: =IFERROR(IF(INDEX(Despesas_DB!C:C,3+MATCH($D$2,Despesas_DB!C4:C99,0)+2)<>$D$2,"",INDEX(Despesas_DB!F:F,3+MATCH($D$2,Despesas_DB!C4:C99,0)+2)),"") -> 13 | F12: =IFERROR(IF(INDEX(Despesas_DB!C:C,3+MATCH($D$2,Despesas_DB!C4:C99,0)+2)<>$D$2,"",INDEX(Despesas_DB!G:G,3+MATCH($D$2,Despesas_DB!C4:C99,0)+2)),"") -> 10 | G12: =IFERROR(IF(INDEX(Despesas_DB!C:C,3+MATCH($D$2,Despesas_DB!C4:C99,0)+2)<>$D$2,"",INDEX(Despesas_DB!H:H,3+MATCH($D$2,Despesas_DB!C4:C99,0)+2)),"") -> 130 | I12: Ampola | J12: =SUMPRODUCT((Despesas_DB!C4:C99=$D$2)*(ISNUMBER(SEARCH(I12,Despesas_DB!E4:E99))*Despesas_DB!H4:H99)) -> 60 | K12: =IFERROR(J12/B5,0) -> 0.015424165
B13: =IFERROR(IF(INDEX(Despesas_DB!C:C,3+MATCH($D$2,Despesas_DB!C4:C99,0)+3)<>$D$2,"",INDEX(Despesas_DB!B:B,3+MATCH($D$2,Despesas_DB!C4:C99,0)+3)),"") -> 2024-10-05 | C13: =IFERROR(IF(INDEX(Despesas_DB!C:C,3+MATCH($D$2,Despesas_DB!C4:C99,0)+3)<>$D$2,"",INDEX(Despesas_DB!D:D,3+MATCH($D$2,Despesas_DB!C4:C99,0)+3)),"") -> Compra de Shampoo | D13: =IFERROR(IF(INDEX(Despesas_DB!C:C,3+MATCH($D$2,Despesas_DB!C4:C99,0)+3)<>$D$2,"",INDEX(Despesas_DB!E:E,3+MATCH($D$2,Despesas_DB!C4:C99,0)+3)),"") -> Shampoo Detox | E13: =IFERROR(IF(INDEX(Despesas_DB!C:C,3+MATCH($D$2,Despesas_DB!C4:C99,0)+3)<>$D$2,"",INDEX(Despesas_DB!F:F,3+MATCH($D$2,Despesas_DB!C4:C99,0)+3)),"") -> 14 | F13: =IFERROR(IF(INDEX(Despesas_DB!C:C,3+MATCH($D$2,Despesas_DB!C4:C99,0)+3)<>$D$2,"",INDEX(Despesas_DB!G:G,3+MATCH($D$2,Despesas_DB!C4:C99,0)+3)),"") -> 20 | G13: =IFERROR(IF(INDEX(Despesas_DB!C:C,3+MATCH($D$2,Despesas_DB!C4:C99,0)+3)<>$D$2,"",INDEX(Despesas_DB!H:H,3+MATCH($D$2,Despesas_DB!C4:C99,0)+3)),"") -> 280 | I13: Máscara | J13: =SUMPRODUCT((Despesas_DB!C4:C99=$D$2)*(ISNUMBER(SEARCH(I13,Despesas_DB!E4:E99))*Despesas_DB!H4:H99)) -> 300 | K13: =IFERROR(J13/B5,0) -> 0.077120823
B14: =IFERROR(IF(INDEX(Despesas_DB!C:C,3+MATCH($D$2,Despesas_DB!C4:C99,0)+4)<>$D$2,"",INDEX(Despesas_DB!B:B,3+MATCH($D$2,Despesas_DB!C4:C99,0)+4)),"") -> 2024-10-06 | C14: =IFERROR(IF(INDEX(Despesas_DB!C:C,3+MATCH($D$2,Despesas_DB!C4:C99,0)+4)<>$D$2,"",INDEX(Despesas_DB!D:D,3+MATCH($D$2,Despesas_DB!C4:C99,0)+4)),"") -> Compra de Shampoo | D14: =IFERROR(IF(INDEX(Despesas_DB!C:C,3+MATCH($D$2,Despesas_DB!C4:C99,0)+4)<>$D$2,"",INDEX(Despesas_DB!E:E,3+MATCH($D$2,Despesas_DB!C4:C99,0)+4)),"") -> Shampoo Antirresíduos | E14: =IFERROR(IF(INDEX(Despesas_DB!C:C,3+MATCH($D$2,Despesas_DB!C4:C99,0)+4)<>$D$2,"",INDEX(Despesas_DB!F:F,3+MATCH($D$2,Despesas_DB!C4:C99,0)+4)),"") -> 17 | F14: =IFERROR(IF(INDEX(Despesas_DB!C:C,3+MATCH($D$2,Despesas_DB!C4:C99,0)+4)<>$D$2,"",INDEX(Despesas_DB!G:G,3+MATCH($D$2,Despesas_DB!C4:C99,0)+4)),"") -> 10 | G14: =IFERROR(IF(INDEX(Despesas_DB!C:C,3+MATCH($D$2,Despesas_DB!C4:C99,0)+4)<>$D$2,"",INDEX(Despesas_DB!H:H,3+MATCH($D$2,Despesas_DB!C4:C99,0)+4)),"") -> 170 | I14: Óleo | J14: =SUMPRODUCT((Despesas_DB!C4:C99=$D$2)*(ISNUMBER(SEARCH(I14,Despesas_DB!E4:E99))*Despesas_DB!H4:H99)) -> 1150 | K14: =IFERROR(J14/B5,0) -> 0.29562982
B15: =IFERROR(IF(INDEX(Despesas_DB!C:C,3+MATCH($D$2,Despesas_DB!C4:C99,0)+5)<>$D$2,"",INDEX(Despesas_DB!B:B,3+MATCH($D$2,Despesas_DB!C4:C99,0)+5)),"") -> 2024-10-07 | C15: =IFERROR(IF(INDEX(Despesas_DB!C:C,3+MATCH($D$2,Despesas_DB!C4:C99,0)+5)<>$D$2,"",INDEX(Despesas_DB!D:D,3+MATCH($D$2,Despesas_DB!C4:C99,0)+5)),"") -> Compra de Shampoo | D15: =IFERROR(IF(INDEX(Despesas_DB!C:C,3+MATCH($D$2,Despesas_DB!C4:C99,0)+5)<>$D$2,"",INDEX(Despesas_DB!E:E,3+MATCH($D$2,Despesas_DB!C4:C99,0)+5)),"") -> Shampoo Reparador | E15: =IFERROR(IF(INDEX(Despesas_DB!C:C,3+MATCH($D$2,Despesas_DB!C4:C99,0)+5)<>$D$2,"",INDEX(Despesas_DB!F:F,3+MATCH($D$2,Despesas_DB!C4:C99,0)+5)),"") -> 18 | F15: =IFERROR(IF(INDEX(Despesas_DB!C:C,3+MATCH($D$2,Despesas_DB!C4:C99,0)+5)<>$D$2,"",INDEX(Despesas_DB!G:G,3+MATCH($D$2,Despesas_DB!C4:C99,0)+5)),"") -> 15 | G15: =IFERROR(IF(INDEX(Despesas_DB!C:C,3+MATCH($D$2,Despesas_DB!C4:C99,0)+5)<>$D$2,"",INDEX(Despesas_DB!H:H,3+MATCH($D$2,Despesas_DB!C4:C99,0)+5)),"") -> 270 | I15: Leave-in | J15: =SUMPRODUCT((Despesas_DB!C4:C99=$D$2)*(ISNUMBER(SEARCH(I15,Despesas_DB!E4:E99))*Despesas_DB!H4:H99)) -> 560 | K15: =IFERROR(J15/B5,0) -> 0.14395887
B16: =IFERROR(IF(INDEX(Despesas_DB!C:C,3+MATCH($D$2,Despesas_DB!C4:C99,0)+6)<>$D$2,"",INDEX(Despesas_DB!B:B,3+MATCH($D$2,Despesas_DB!C4:C99,0)+6)),"") -> 2024-10-08 | C16: =IFERROR(IF(INDEX(Despesas_DB!C:C,3+MATCH($D$2,Despesas_DB!C4:C99,0)+6)<>$D$2,"",INDEX(Despesas_DB!D:D,3+MATCH($D$2,Despesas_DB!C4:C99,0)+6)),"") -> Compra de Condicionador | D16: =IFERROR(IF(INDEX(Despesas_DB!C:C,3+MATCH($D$2,Despesas_DB!C4:C99,0)+6)<>$D$2,"",INDEX(Despesas_DB!E:E,3+MATCH($D$2,Despesas_DB!C4:C99,0)+6)),"") -> Condicionador Revitalizante | E16: =IFERROR(IF(INDEX(Despesas_DB!C:C,3+MATCH($D$2,Despesas_DB!C4:C99,0)+6)<>$D$2,"",INDEX(Despesas_DB!F:F,3+MATCH($D$2,Despesas_DB!C4:C99,0)+6)),"") -> 17 | F16: =IFERROR(IF(INDEX(Despesas_DB!C:C,3+MATCH($D$2,Despesas_DB!C4:C99,0)+6)<>$D$2,"",INDEX(Despesas_DB!G:G,3+MATCH($D$2,Despesas_DB!C4:C99,0)+6)),"") -> 15 | G16: =IFERROR(IF(INDEX(Despesas_DB!C:C,3+MATCH($D$2,Despesas_DB!C4:C99,0)+6)<>$D$2,"",INDEX(Despesas_DB!H:H,3+MATCH($D$2,Despesas_DB!C4:C99,0)+6)),"") -> 255 | I16: Creme de Pentear | J16: =SUMPRODUCT((Despesas_DB!C4:C99=$D$2)*(ISNUMBER(SEARCH(I16,Despesas_DB!E4:E99))*Despesas_DB!H4:H99)) -> 430 | K16: =IFERROR(J16/B5,0) -> 0.11053985
B17: =IFERROR(IF(INDEX(Despesas_DB!C:C,3+MATCH($D$2,Despesas_DB!C4:C99,0)+7)<>$D$2,"",INDEX(Despesas_DB!B:B,3+MATCH($D$2,Despesas_DB!C4:C99,0)+7)),"") -> 2024-10-09 | C17: =IFERROR(IF(INDEX(Despesas_DB!C:C,3+MATCH($D$2,Despesas_DB!C4:C99,0)+7)<>$D$2,"",INDEX(Despesas_DB!D:D,3+MATCH($D$2,Despesas_DB!C4:C99,0)+7)),"") -> Compra de Condicionador | D17: =IFERROR(IF(INDEX(Despesas_DB!C:C,3+MATCH($D$2,Despesas_DB!C4:C99,0)+7)<>$D$2,"",INDEX(Despesas_DB!E:E,3+MATCH($D$2,Despesas_DB!C4:C99,0)+7)),"") -> Condicionador Nutritivo | E17: =IFERROR(IF(INDEX(Despesas_DB!C:C,3+MATCH($D$2,Despesas_DB!C4:C99,0)+7)<>$D$2,"",INDEX(Despesas_DB!F:F,3+MATCH($D$2,Despesas_DB!C4:C99,0)+7)),"") -> 15 | F17: =IFERROR(IF(INDEX(Despesas_DB!C:C,3+MATCH($D$2,Despesas_DB!C4:C99,0)+7)<>$D$2,"",INDEX(Despesas_DB!G:G,3+MATCH($D$2,Despesas_DB!C4:C99,0)+7)),"") -> 15 | G17: =IFERROR(IF(INDEX(Despesas_DB!C:C,3+MATCH($D$2,Despesas_DB!C4:C99,0)+7)<>$D$2,"",INDEX(Despesas_DB!H:H,3+MATCH($D$2,Despesas_DB!C4:C99,0)+7)),"") -> 225
B18: =IFERROR(IF(INDEX(Despesas_DB!C:C,3+MATCH($D$2,Despesas_DB!C4:C99,0)+8)<>$D$2,"",INDEX(Despesas_DB!B:B,3+MATCH($D$2,Despesas_DB!C4:C99,0)+8)),"") -> 2024-10-10 | C18: =IFERROR(IF(INDEX(Despesas_DB!C:C,3+MATCH($D$2,Despesas_DB!C4:C99,0)+8)<>$D$2,"",INDEX(Despesas_DB!D:D,3+MATCH($D$2,Despesas_DB!C4:C99,0)+8)),"") -> Compra de Máscara | D18: =IFERROR(IF(INDEX(Despesas_DB!C:C,3+MATCH($D$2,Despesas_DB!C4:C99,0)+8)<>$D$2,"",INDEX(Despesas_DB!E:E,3+MATCH($D$2,Despesas_DB!C4:C99,0)+8)),"") -> Máscara de Reconstrução | E18: =IFERROR(IF(INDEX(Despesas_DB!C:C,3+MATCH($D$2,Despesas_DB!C4:C99,0)+8)<>$D$2,"",INDEX(Despesas_DB!F:F,3+MATCH($D$2,Despesas_DB!C4:C99,0)+8)),"") -> 30 | F18: =IFERROR(IF(INDEX(Despesas_DB!C:C,3+MATCH($D$2,Despesas_DB!C4:C99,0)+8)<>$D$2,"",INDEX(Despesas_DB!G:G,3+MATCH($D$2,Despesas_DB!C4:C99,0)+8)),"") -> 10 | G18: =IFERROR(IF(INDEX(Despesas_DB!C:C,3+MATCH($D$2,Despesas_DB!C4:C99,0)+8)<>$D$2,"",INDEX(Despesas_DB!H:H,3+MATCH($D$2,Despesas_DB!C4:C99,0)+8)),"") -> 300
B19: =IFERROR(IF(INDEX(Despesas_DB!C:C,3+MATCH($D$2,Despesas_DB!C4:C99,0)+9)<>$D$2,"",INDEX(Despesas_DB!B:B,3+MATCH($D$2,Despesas_DB!C4:C99,0)+9)),"") -> 2024-10-11 | C19: =IFERROR(IF(INDEX(Despesas_DB!C:C,3+MATCH($D$2,Despesas_DB!C4:C99,0)+9)<>$D$2,"",INDEX(Despesas_DB!D:D,3+MATCH($D$2,Despesas_DB!C4:C99,0)+9)),"") -> Compra de Condicionador | D19: =IFERROR(IF(INDEX(Despesas_DB!C:C,3+MATCH($D$2,Despesas_DB!C4:C99,0)+9)<>$D$2,"",INDEX(Despesas_DB!E:E,3+MATCH($D$2,Despesas_DB!C4:C99,0)+9)),"") -> Condicionador Antifrizz | E19: =IFERROR(IF(INDEX(Despesas_DB!C:C,3+MATCH($D$2,Despesas_DB!C4:C99,0)+9)<>$D$2,"",INDEX(Despesas_DB!F:F,3+MATCH($D$2,Despesas_DB!C4:C99,0)+9)),"") -> 19 | F19: =IFERROR(IF(INDEX(Despesas_DB!C:C,3+MATCH($D$2,Despesas_DB!C4:C99,0)+9)<>$D$2,"",INDEX(Despesas_DB!G:G,3+MATCH($D$2,Despesas_DB!C4:C99,0)+9)),"") -> 10 | G19: =IFERROR(IF(INDEX(Despesas_DB!C:C,3+MATCH($D$2,Despesas_DB!C4:C99,0)+9)<>$D$2,"",INDEX(Despesas_DB!H:H,3+MATCH($D$2,Despesas_DB!C4:C99,0)+9)),"") -> 190
B20: =IFERROR(IF(INDEX(Despesas_DB!C:C,3+MATCH($D$2,Despesas_DB!C4:C99,0)+10)<>$D$2,"",INDEX(Despesas_DB!B:B,3+MATCH($D$2,Despesas_DB!C4:C99,0)+10)),"") -> 2024-10-13 | C20: =IFERROR(IF(INDEX(Despesas_DB!C:C,3+MATCH($D$2,Despesas_DB!C4:C99,0)+10)<>$D$2,"",INDEX(Despesas_DB!D:D,3+MATCH($D$2,Despesas_DB!C4:C99,0)+10)),"") -> Compra de Óleo | D20: =IFERROR(IF(INDEX(Despesas_DB!C:C,3+MATCH($D$2,Despesas_DB!C4:C99,0)+10)<>$D$2,"",INDEX(Despesas_DB!E:E,3+MATCH($D$2,Despesas_DB!C4:C99,0)+10)),"") -> Óleo de Jojoba | E20: =IFERROR(IF(INDEX(Despesas_DB!C:C,3+MATCH($D$2,Despesas_DB!C4:C99,0)+10)<>$D$2,"",INDEX(Despesas_DB!F:F,3+MATCH($D$2,Despesas_DB!C4:C99,0)+10)),"") -> 17 | F20: =IFERROR(IF(INDEX(Despesas_DB!C:C,3+MATCH($D$2,Despesas_DB!C4:C99,0)+10)<>$D$2,"",INDEX(Despesas_DB!G:G,3+MATCH($D$2,Despesas_DB!C4:C99,0)+10)),"") -> 20 | G20: =IFERROR(IF(INDEX(Despesas_DB!C:C,3+MATCH($D$2,Despesas_DB!C4:C99,0)+10)<>$D$2,"",INDEX(Despesas_DB!H:H,3+MATCH($D$2,Despesas_DB!C4:C99,0)+10)),"") -> 340
B21: =IFERROR(IF(INDEX(Despesas_DB!C:C,3+MATCH($D$2,Despesas_DB!C4:C99,0)+11)<>$D$2,"",INDEX(Despesas_DB!B:B,3+MATCH($D$2,Despesas_DB!C4:C99,0)+11)),"") -> 2024-10-14 | C21: =IFERROR(IF(INDEX(Despesas_DB!C:C,3+MATCH($D$2,Despesas_DB!C4:C99,0)+11)<>$D$2,"",INDEX(Despesas_DB!D:D,3+MATCH($D$2,Despesas_DB!C4:C99,0)+11)),"") -> Compra de Leave-in | D21: =IFERROR(IF(INDEX(Despesas_DB!C:C,3+MATCH($D$2,Despesas_DB!C4:C99,0)+11)<>$D$2,"",INDEX(Despesas_DB!E:E,3+MATCH($D$2,Despesas_DB!C4:C99,0)+11)),"") -> Leave-in Nutritivo | E21: =IFERROR(IF(INDEX(Despesas_DB!C:C,3+MATCH($D$2,Despesas_DB!C4:C99,0)+11)<>$D$2,"",INDEX(Despesas_DB!F:F,3+MATCH($D$2,Despesas_DB!C4:C99,0)+11)),"") -> 14 | F21: =IFERROR(IF(INDEX(Despesas_DB!C:C,3+MATCH($D$2,Despesas_DB!C4:C99,0)+11)<>$D$2,"",INDEX(Despesas_DB!G:G,3+MATCH($D$2,Despesas_DB!C4:C99,0)+11)),"") -> 10 | G21: =IFERROR(IF(INDEX(Despesas_DB!C:C,3+MATCH($D$2,Despesas_DB!C4:C99,0)+11)<>$D$2,"",INDEX(Despesas_DB!H:H,3+MATCH($D$2,Despesas_DB!C4:C99,0)+11)),"") -> 140
B22: =IFERROR(IF(INDEX(Despesas_DB!C:C,3+MATCH($D$2,Despesas_DB!C4:C99,0)+12)<>$D$2,"",INDEX(Despesas_DB!B:B,3+MATCH($D$2,Despesas_DB!C4:C99,0)+12)),"") -> 2024-10-15 | C22: =IFERROR(IF(INDEX(Despesas_DB!C:C,3+MATCH($D$2,Despesas_DB!C4:C99,0)+12)<>$D$2,"",INDEX(Despesas_DB!D:D,3+MATCH($D$2,Despesas_DB!C4:C99,0)+12)),"") -> Compra de Leave-in | D22: =IFERROR(IF(INDEX(Despesas_DB!C:C,3+MATCH($D$2,Despesas_DB!C4:C99,0)+12)<>$D$2,"",INDEX(Despesas_DB!E:E,3+MATCH($D$2,Despesas_DB!C4:C99,0)+12)),"") -> Leave-in para Cabelos Cacheados | E22: =IFERROR(IF(INDEX(Despesas_DB!C:C,3+MATCH($D$2,Despesas_DB!C4:C99,0)+12)<>$D$2,"",INDEX(Despesas_DB!F:F,3+MATCH($D$2,Despesas_DB!C4:C99,0)+12)),"") -> 16 | F22: =IFERROR(IF(INDEX(Despesas_DB!C:C,3+MATCH($D$2,Despesas_DB!C4:C99,0)+12)<>$D$2,"",INDEX(Despesas_DB!G:G,3+MATCH($D$2,Despesas_DB!C4:C99,0)+12)),"") -> 15 | G22: =IFERROR(IF(INDEX(Despesas_DB!C:C,3+MATCH($D$2,Despesas_DB!C4:C99,0)+12)<>$D$2,"",INDEX(Despesas_DB!H:H,3+MATCH($D$2,Despesas_DB!C4:C99,0)+12)),"") -> 240
B23: =IFERROR(IF(INDEX(Despesas_DB!C:C,3+MATCH($D$2,Despesas_DB!C4:C99,0)+13)<>$D$2,"",INDEX(Despesas_DB!B:B,3+MATCH($D$2,Despesas_DB!C4:C99,0)+13)),"") -> 2024-10-16 | C23: =IFERROR(IF(INDEX(Despesas_DB!C:C,3+MATCH($D$2,Despesas_DB!C4:C99,0)+13)<>$D$2,"",INDEX(Despesas_DB!D:D,3+MATCH($D$2,Despesas_DB!C4:C99,0)+13)),"") -> Compra de Leave-in | D23: =IFERROR(IF(INDEX(Despesas_DB!C:C,3+MATCH($D$2,Despesas_DB!C4:C99,0)+13)<>$D$2,"",INDEX(Despesas_DB!E:E,3+MATCH($D$2,Despesas_DB!C4:C99,0)+13)),"") -> Leave-in Hidratante | E23: =IFERROR(IF(INDEX(Despesas_DB!C:C,3+MATCH($D$2,Despesas_DB!C4:C99,0)+13)<>$D$2,"",INDEX(Despesas_DB!F:F,3+MATCH($D$2,Despesas_DB!C4:C99,0)+13)),"") -> 12 | F23: =IFERROR(IF(INDEX(Despesas_DB!C:C,3+MATCH($D$2,Despesas_DB!C4:C99,0)+13)<>$D$2,"",INDEX(Despesas_DB!G:G,3+MATCH($D$2,Despesas_DB!C4:C99,0)+13)),"") -> 15 | G23: =IFERROR(IF(INDEX(Despesas_DB!C:C,3+MATCH($D$2,Despesas_DB!C4:C99,0)+13)<>$D$2,"",INDEX(Despesas_DB!H:H,3+MATCH($D$2,Despesas_DB!C4:C99,0)+13)),"") -> 180
B24: =IFERROR(IF(INDEX(Despesas_DB!C:C,3+MATCH($D$2,Despesas_DB!C4:C99,0)+14)<>$D$2,"",INDEX(Despesas_DB!B:B,3+MATCH($D$2,Despesas_DB!C4:C99,0)+14)),"") -> 2024-10-17 | C24: =IFERROR(IF(INDEX(Despesas_DB!C:C,3+MATCH($D$2,Despesas_DB!C4:C99,0)+14)<>$D$2,"",INDEX(Despesas_DB!D:D,3+MATCH($D$2,Despesas_DB!C4:C99,0)+14)),"") -> Compra de Creme de Pentear | D24: =IFERROR(IF(INDEX(Despesas_DB!C:C,3+MATCH($D$2,Despesas_DB!C4:C99,0)+14)<>$D$2,"",INDEX(Despesas_DB!E:E,3+MATCH($D$2,Despesas_DB!C4:C99,0)+14)),"") -> Creme de Pentear Modelador de Cachos | E24: =IFERROR(IF(INDEX(Despesas_DB!C:C,3+MATCH($D$2,Despesas_DB!C4:C99,0)+14)<>$D$2,"",INDEX(Despesas_DB!F:F,3+MATCH($D$2,Despesas_DB!C4:C99,0)+14)),"") -> 10 | F24: =IFERROR(IF(INDEX(Despesas_DB!C:C,3+MATCH($D$2,Despesas_DB!C4:C99,0)+14)<>$D$2,"",INDEX(Despesas_DB!G:G,3+MATCH($D$2,Despesas_DB!C4:C99,0)+14)),"") -> 10 | G24: =IFERROR(IF(INDEX(Despesas_DB!C:C,3+MATCH($D$2,Despesas_DB!C4:C99,0)+14)<>$D$2,"",INDEX(Despesas_DB!H:H,3+MATCH($D$2,Despesas_DB!C4:C99,0)+14)),"") -> 100
B25: =IFERROR(IF(INDEX(Despesas_DB!C:C,3+MATCH($D$2,Despesas_DB!C4:C99,0)+15)<>$D$2,"",INDEX(Despesas_DB!B:B,3+MATCH($D$2,Despesas_DB!C4:C99,0)+15)),"") -> 2024-10-18 | C25: =IFERROR(IF(INDEX(Despesas_DB!C:C,3+MATCH($D$2,Despesas_DB!C4:C99,0)+15)<>$D$2,"",INDEX(Despesas_DB!D:D,3+MATCH($D$2,Despesas_DB!C4:C99,0)+15)),"") -> Compra de Óleo | D25: =IFERROR(IF(INDEX(Despesas_DB!C:C,3+MATCH($D$2,Despesas_DB!C4:C99,0)+15)<>$D$2,"",INDEX(Despesas_DB!E:E,3+MATCH($D$2,Despesas_DB!C4:C99,0)+15)),"") -> Óleo de Argan | E25: =IFERROR(IF(INDEX(Despesas_DB!C:C,3+MATCH($D$2,Despesas_DB!C4:C99,0)+15)<>$D$2,"",INDEX(Despesas_DB!F:F,3+MATCH($D$2,Despesas_DB!C4:C99,0)+15)),"") -> 15 | F25: =IFERROR(IF(INDEX(Despesas_DB!C:C,3+MATCH($D$2,Despesas_DB!C4:C99,0)+15)<>$D$2,"",INDEX(Despesas_DB!G:G,3+MATCH($D$2,Despesas_DB!C4:C99,0)+15)),"") -> 30 | G25: =IFERROR(IF(INDEX(Despesas_DB!C:C,3+MATCH($D$2,Despesas_DB!C4:C99,0)+15)<>$D$2,"",INDEX(Despesas_DB!H:H,3+MATCH($D$2,Despesas_DB!C4:C99,0)+15)),"") -> 450
B26: =IFERROR(IF(INDEX(Despesas_DB!C:C,3+MATCH($D$2,Despesas_DB!C4:C99,0)+16)<>$D$2,"",INDEX(Despesas_DB!B:B,3+MATCH($D$2,Despesas_DB!C4:C99,0)+16)),"") -> 2024-10-20 | C26: =IFERROR(IF(INDEX(Despesas_DB!C:C,3+MATCH($D$2,Despesas_DB!C4:C99,0)+16)<>$D$2,"",INDEX(Despesas_DB!D:D,3+MATCH($D$2,Despesas_DB!C4:C99,0)+16)),"") -> Compra de Ampola | D26: =IFERROR(IF(INDEX(Despesas_DB!C:C,3+MATCH($D$2,Despesas_DB!C4:C99,0)+16)<>$D$2,"",INDEX(Despesas_DB!E:E,3+MATCH($D$2,Despesas_DB!C4:C99,0)+16)),"") -> Ampola de Fortalecimento | E26: =IFERROR(IF(INDEX(Despesas_DB!C:C,3+MATCH($D$2,Despesas_DB!C4:C99,0)+16)<>$D$2,"",INDEX(Despesas_DB!F:F,3+MATCH($D$2,Despesas_DB!C4:C99,0)+16)),"") -> 6 | F26: =IFERROR(IF(INDEX(Despesas_DB!C:C,3+MATCH($D$2,Despesas_DB!C4:C99,0)+16)<>$D$2,"",INDEX(Despesas_DB!G:G,3+MATCH($D$2,Despesas_DB!C4:C99,0)+16)),"") -> 10 | G26: =IFERROR(IF(INDEX(Despesas_DB!C:C,3+MATCH($D$2,Despesas_DB!C4:C99,0)+16)<>$D$2,"",INDEX(Despesas_DB!H:H,3+MATCH($D$2,Despesas_DB!C4:C99,0)+16)),"") -> 60
B27: =IFERROR(IF(INDEX(Despesas_DB!C:C,3+MATCH($D$2,Despesas_DB!C4:C99,0)+17)<>$D$2,"",INDEX(Despesas_DB!B:B,3+MATCH($D$2,Despesas_DB!C4:C99,0)+17)),"") | C27: =IFERROR(IF(INDEX(Despesas_DB!C:C,3+MATCH($D$2,Despesas_DB!C4:C99,0)+17)<>$D$2,"",INDEX(Despesas_DB!D:D,3+MATCH($D$2,Despesas_DB!C4:C99,0)+17)),"") | D27: =IFERROR(IF(INDEX(Despesas_DB!C:C,3+MATCH($D$2,Despesas_DB!C4:C99,0)+17)<>$D$2,"",INDEX(Despesas_DB!E:E,3+MATCH($D$2,Despesas_DB!C4:C99,0)+17)),"") | E27: =IFERROR(IF(INDEX(Despesas_DB!C:C,3+MATCH($D$2,Despesas_DB!C4:C99,0)+17)<>$D$2,"",INDEX(Despesas_DB!F:F,3+MATCH($D$2,Despesas_DB!C4:C99,0)+17)),"") | F27: =IFERROR(IF(INDEX(Despesas_DB!C:C,3+MATCH($D$2,Despesas_DB!C4:C99,0)+17)<>$D$2,"",INDEX(Despesas_DB!G:G,3+MATCH($D$2,Despesas_DB!C4:C99,0)+17)),"") | G27: =IFERROR(IF(INDEX(Despesas_DB!C:C,3+MATCH($D$2,Despesas_DB!C4:C99,0)+17)<>$D$2,"",INDEX(Despesas_DB!H:H,3+MATCH($D$2,Despesas_DB!C4:C99,0)+17)),"")
B28: =IFERROR(IF(INDEX(Despesas_DB!C:C,3+MATCH($D$2,Despesas_DB!C4:C99,0)+18)<>$D$2,"",INDEX(Despesas_DB!B:B,3+MATCH($D$2,Despesas_DB!C4:C99,0)+18)),"") | C28: =IFERROR(IF(INDEX(Despesas_DB!C:C,3+MATCH($D$2,Despesas_DB!C4:C99,0)+18)<>$D$2,"",INDEX(Despesas_DB!D:D,3+MATCH($D$2,Despesas_DB!C4:C99,0)+18)),"") | D28: =IFERROR(IF(INDEX(Despesas_DB!C:C,3+MATCH($D$2,Despesas_DB!C4:C99,0)+18)<>$D$2,"",INDEX(Despesas_DB!E:E,3+MATCH($D$2,Despesas_DB!C4:C99,0)+18)),"") | E28: =IFERROR(IF(INDEX(Despesas_DB!C:C,3+MATCH($D$2,Despesas_DB!C4:C99,0)+18)<>$D$2,"",INDEX(Despesas_DB!F:F,3+MATCH($D$2,Despesas_DB!C4:C99,0)+18)),"") | F28: =IFERROR(IF(INDEX(Despesas_DB!C:C,3+MATCH($D$2,Despesas_DB!C4:C99,0)+18)<>$D$2,"",INDEX(Despesas_DB!G:G,3+MATCH($D$2,Despesas_DB!C4:C99,0)+18)),"") | G28: =IFERROR(IF(INDEX(Despesas_DB!C:C,3+MATCH($D$2,Despesas_DB!C4:C99,0)+18)<>$D$2,"",INDEX(Despesas_DB!H:H,3+MATCH($D$2,Despesas_DB!C4:C99,0)+18)),"")
B29: =IFERROR(IF(INDEX(Despesas_DB!C:C,3+MATCH($D$2,Despesas_DB!C4:C99,0)+19)<>$D$2,"",INDEX(Despesas_DB!B:B,3+MATCH($D$2,Despesas_DB!C4:C99,0)+19)),"") | C29: =IFERROR(IF(INDEX(Despesas_DB!C:C,3+MATCH($D$2,Despesas_DB!C4:C99,0)+19)<>$D$2,"",INDEX(Despesas_DB!D:D,3+MATCH($D$2,Despesas_DB!C4:C99,0)+19)),"") | D29: =IFERROR(IF(INDEX(Despesas_DB!C:C,3+MATCH($D$2,Despesas_DB!C4:C99,0)+19)<>$D$2,"",INDEX(Despesas_DB!E:E,3+MATCH($D$2,Despesas_DB!C4:C99,0)+19)),"") | E29: =IFERROR(IF(INDEX(Despesas_DB!C:C,3+MATCH($D$2,Despesas_DB!C4:C99,0)+19)<>$D$2,"",INDEX(Despesas_DB!F:F,3+MATCH($D$2,Despesas_DB!C4:C99,0)+19)),"") | F29: =IFERROR(IF(INDEX(Despesas_DB!C:C,3+MATCH($D$2,Despesas_DB!C4:C99,0)+19)<>$D$2,"",INDEX(Despesas_DB!G:G,3+MATCH($D$2,Despesas_DB!C4:C99,0)+19)),"") | G29: =IFERROR(IF(INDEX(Despesas_DB!C:C,3+MATCH($D$2,Despesas_DB!C4:C99,0)+19)<>$D$2,"",INDEX(Despesas_DB!H:H,3+MATCH($D$2,Despesas_DB!C4:C99,0)+19)),"")

Sheet Lucro
B1: 📈 ANÁLISE DE LUCRO
B2: 📅 Filtro de Mês: | D2: Outubro | G2: ⬅ Selecione o mês para atualizar
B4: 💰 Faturamento | C4: 💸 Custo Total | E4: 📈 Lucro | F4: 📊 Margem | G4: 💡 Rentab.
B5: =SUMIF(Pedidos_DB!C4:C110,$D$2,Pedidos_DB!G4:G110) -> 8328.2 | C5: =SUMIF(Despesas_DB!C4:C99,$D$2,Despesas_DB!H4:H99) -> 3890 | E5: =B5-C5 -> 4438.2 | F5: =IFERROR(E5/B5,0) -> 0.53291227 | G5: =IFERROR(E5/C5,0) -> 1.1409254
B8: 🏆 Lucro por Produto
B9: Produto | C9: Qtd Vendida | D9: Faturamento | E9: Custo | F9: Lucro | G9: Margem
B10: Shampoo Antiqueda | C10: =SUMPRODUCT((Pedidos_DB!C4:C110=$D$2)*(Pedidos_DB!E4:E110=B10)*Pedidos_DB!F4:F110) -> 20 | D10: =SUMPRODUCT((Pedidos_DB!C4:C110=$D$2)*(Pedidos_DB!E4:E110=B10)*Pedidos_DB!G4:G110) -> 378 | E10: =SUMIFS(Despesas_DB!H4:H99,Despesas_DB!C4:C99,$D$2,Despesas_DB!E4:E99,B10) -> 0 | F10: =D10-E10 -> 378 | G10: =IFERROR(F10/D10,0) -> 1
B11: Condicionador Nutritivo | C11: =SUMPRODUCT((Pedidos_DB!C4:C110=$D$2)*(Pedidos_DB!E4:E110=B11)*Pedidos_DB!F4:F110) -> 22 | D11: =SUMPRODUCT((Pedidos_DB!C4:C110=$D$2)*(Pedidos_DB!E4:E110=B11)*Pedidos_DB!G4:G110) -> 426.8 | E11: =SUMIFS(Despesas_DB!H4:H99,Despesas_DB!C4:C99,$D$2,Despesas_DB!E4:E99,B11) -> 225 | F11: =D11-E11 -> 201.8 | G11: =IFERROR(F11/D11,0) -> 0.47282099
B12: Ampola de Reparação | C12: =SUMPRODUCT((Pedidos_DB!C4:C110=$D$2)*(Pedidos_DB!E4:E110=B12)*Pedidos_DB!F4:F110) -> 5 | D12: =SUMPRODUCT((Pedidos_DB!C4:C110=$D$2)*(Pedidos_DB!E4:E110=B12)*Pedidos_DB!G4:G110) -> 62.5 | E12: =SUMIFS(Despesas_DB!H4:H99,Despesas_DB!C4:C99,$D$2,Despesas_DB!E4:E99,B12) -> 0 | F12: =D12-E12 -> 62.5 | G12: =IFERROR(F12/D12,0) -> 1
B13: Máscara de Hidratação | C13: =SUMPRODUCT((Pedidos_DB!C4:C110=$D$2)*(Pedidos_DB!E4:E110=B13)*Pedidos_DB!F4:F110) -> 15 | D13: =SUMPRODUCT((Pedidos_DB!C4:C110=$D$2)*(Pedidos_DB!E4:E110=B13)*Pedidos_DB!G4:G110) -> 525 | E13: =SUMIFS(Despesas_DB!H4:H99,Despesas_DB!C4:C99,$D$2,Despesas_DB!E4:E99,B13) -> 0 | F13: =D13-E13 -> 525 | G13: =IFERROR(F13/D13,0) -> 1
B14: Óleo de Rícino | C14: =SUMPRODUCT((Pedidos_DB!C4:C110=$D$2)*(Pedidos_DB!E4:E110=B14)*Pedidos_DB!F4:F110) -> 20 | D14: =SUMPRODUCT((Pedidos_DB!C4:C110=$D$2)*(Pedidos_DB!E4:E110=B14)*Pedidos_DB!G4:G110) -> 400 | E14: =SUMIFS(Despesas_DB!H4:H99,Despesas_DB!C4:C99,$D$2,Despesas_DB!E4:E99,B14) -> 360 | F14: =D14-E14 -> 40 | G14: =IFERROR(F14/D14,0) -> 0.1
B15: Creme de Pentear Hidratante | C15: =SUMPRODUCT((Pedidos_DB!C4:C110=$D$2)*(Pedidos_DB!E4:E110=B15)*Pedidos_DB!F4:F110) -> 10 | D15: =SUMPRODUCT((Pedidos_DB!C4:C110=$D$2)*(Pedidos_DB!E4:E110=B15)*Pedidos_DB!G4:G110) -> 182 | E15: =SUMIFS(Despesas_DB!H4:H99,Despesas_DB!C4:C99,$D$2,Despesas_DB!E4:E99,B15) -> 130 | F15: =D15-E15 -> 52 | G15: =IFERROR(F15/D15,0) -> 0.28571429
B16: Shampoo Detox | C16: =SUMPRODUCT((Pedidos_DB!C4:C110=$D$2)*(Pedidos_DB!E4:E110=B16)*Pedidos_DB!F4:F110) -> 15 | D16: =SUMPRODUCT((Pedidos_DB!C4:C110=$D$2)*(Pedidos_DB!E4:E110=B16)*Pedidos_DB!G4:G110) -> 298.5 | E16: =SUMIFS(Despesas_DB!H4:H99,Despesas_DB!C4:C99,$D$2,Despesas_DB!E4:E99,B16) -> 280 | F16: =D16-E16 -> 18.5 | G16: =IFERROR(F16/D16,0) -> 0.061976549
B17: Máscara de Nutrição Profunda | C17: =SUMPRODUCT((Pedidos_DB!C4:C110=$D$2)*(Pedidos_DB!E4:E110=B17)*Pedidos_DB!F4:F110) -> 30 | D17: =SUMPRODUCT((Pedidos_DB!C4:C110=$D$2)*(Pedidos_DB!E4:E110=B17)*Pedidos_DB!G4:G110) -> 1260 | E17: =SUMIFS(Despesas_DB!H4:H99,Despesas_DB!C4:C99,$D$2,Despesas_DB!E4:E99,B17) -> 0 | F17: =D17-E17 -> 1260 | G17: =IFERROR(F17/D17,0) -> 1
B18: Leave-in Nutritivo | C18: =SUMPRODUCT((Pedidos_DB!C4:C110=$D$2)*(Pedidos_DB!E4:E110=B18)*Pedidos_DB!F4:F110) -> 0 | D18: =SUMPRODUCT((Pedidos_DB!C4:C110=$D$2)*(Pedidos_DB!E4:E110=B18)*Pedidos_DB!G4:G110) -> 0 | E18: =SUMIFS(Despesas_DB!H4:H99,Despesas_DB!C4:C99,$D$2,Despesas_DB!E4:E99,B18) -> 140 | F18: =D18-E18 -> -140 | G18: =IFERROR(F18/D18,0) -> 0
B19: Condicionador Antifrizz | C19: =SUMPRODUCT((Pedidos_DB!C4:C110=$D$2)*(Pedidos_DB!E4:E110=B19)*Pedidos_DB!F4:F110) -> 10 | D19: =SUMPRODUCT((Pedidos_DB!C4:C110=$D$2)*(Pedidos_DB!E4:E110=B19)*Pedidos_DB!G4:G110) -> 271 | E19: =SUMIFS(Despesas_DB!H4:H99,Despesas_DB!C4:C99,$D$2,Despesas_DB!E4:E99,B19) -> 190 | F19: =D19-E19 -> 81 | G19: =IFERROR(F19/D19,0) -> 0.29889299
B20: Óleo de Argan | C20: =SUMPRODUCT((Pedidos_DB!C4:C110=$D$2)*(Pedidos_DB!E4:E110=B20)*Pedidos_DB!F4:F110) -> 8 | D20: =SUMPRODUCT((Pedidos_DB!C4:C110=$D$2)*(Pedidos_DB!E4:E110=B20)*Pedidos_DB!G4:G110) -> 239.2 | E20: =SUMIFS(Despesas_DB!H4:H99,Despesas_DB!C4:C99,$D$2,Despesas_DB!E4:E99,B20) -> 450 | F20: =D20-E20 -> -210.8 | G20: =IFERROR(F20/D20,0) -> -0.8812709
B21: Máscara Reconstrutora | C21: =SUMPRODUCT((Pedidos_DB!C4:C110=$D$2)*(Pedidos_DB!E4:E110=B21)*Pedidos_DB!F4:F110) -> 12 | D21: =SUMPRODUCT((Pedidos_DB!C4:C110=$D$2)*(Pedidos_DB!E4:E110=B21)*Pedidos_DB!G4:G110) -> 480 | E21: =SUMIFS(Despesas_DB!H4:H99,Despesas_DB!C4:C99,$D$2,Despesas_DB!E4:E99,B21) -> 0 | F21: =D21-E21 -> 480 | G21: =IFERROR(F21/D21,0) -> 1
B22: Creme de Pentear Antifrizz | C22: =SUMPRODUCT((Pedidos_DB!C4:C110=$D$2)*(Pedidos_DB!E4:E110=B22)*Pedidos_DB!F4:F110) -> 25 | D22: =SUMPRODUCT((Pedidos_DB!C4:C110=$D$2)*(Pedidos_DB!E4:E110=B22)*Pedidos_DB!G4:G110) -> 375 | E22: =SUMIFS(Despesas_DB!H4:H99,Despesas_DB!C4:C99,$D$2,Despesas_DB!E4:E99,B22) -> 200 | F22: =D22-E22 -> 175 | G22: =IFERROR(F22/D22,0) -> 0.46666667
B23: Shampoo Antirresíduos | C23: =SUMPRODUCT((Pedidos_DB!C4:C110=$D$2)*(Pedidos_DB!E4:E110=B23)*Pedidos_DB!F4:F110) -> 10 | D23: =SUMPRODUCT((Pedidos_DB!C4:C110=$D$2)*(Pedidos_DB!E4:E110=B23)*Pedidos_DB!G4:G110) -> 235 | E23: =SUMIFS(Despesas_DB!H4:H99,Despesas_DB!C4:C99,$D$2,Despesas_DB!E4:E99,B23) -> 170 | F23: =D23-E23 -> 65 | G23: =IFERROR(F23/D23,0) -> 0.27659574
B24: Shampoo Reparador | C24: =SUMPRODUCT((Pedidos_DB!C4:C110=$D$2)*(Pedidos_DB!E4:E110=B24)*Pedidos_DB!F4:F110) -> 18 | D24: =SUMPRODUCT((Pedidos_DB!C4:C110=$D$2)*(Pedidos_DB!E4:E110=B24)*Pedidos_DB!G4:G110) -> 450 | E24: =SUMIFS(Despesas_DB!H4:H99,Despesas_DB!C4:C99,$D$2,Despesas_DB!E4:E99,B24) -> 270 | F24: =D24-E24 -> 180 | G24: =IFERROR(F24/D24,0) -> 0.4
B25: Condicionador Revitalizante | C25: =SUMPRODUCT((Pedidos_DB!C4:C110=$D$2)*(Pedidos_DB!E4:E110=B25)*Pedidos_DB!F4:F110) -> 20 | D25: =SUMPRODUCT((Pedidos_DB!C4:C110=$D$2)*(Pedidos_DB!E4:E110=B25)*Pedidos_DB!G4:G110) -> 438 | E25: =SUMIFS(Despesas_DB!H4:H99,Despesas_DB!C4:C99,$D$2,Despesas_DB!E4:E99,B25) -> 255 | F25: =D25-E25 -> 183 | G25: =IFERROR(F25/D25,0) -> 0.41780822
B26: Condicionador Hidratante | C26: =SUMPRODUCT((Pedidos_DB!C4:C110=$D$2)*(Pedidos_DB!E4:E110=B26)*Pedidos_DB!F4:F110) -> 22 | D26: =SUMPRODUCT((Pedidos_DB!C4:C110=$D$2)*(Pedidos_DB!E4:E110=B26)*Pedidos_DB!G4:G110) -> 360.8 | E26: =SUMIFS(Despesas_DB!H4:H99,Despesas_DB!C4:C99,$D$2,Despesas_DB!E4:E99,B26) -> 0 | F26: =D26-E26 -> 360.8 | G26: =IFERROR(F26/D26,0) -> 1
B27: Óleo de Jojoba | C27: =SUMPRODUCT((Pedidos_DB!C4:C110=$D$2)*(Pedidos_DB!E4:E110=B27)*Pedidos_DB!F4:F110) -> 15 | D27: =SUMPRODUCT((Pedidos_DB!C4:C110=$D$2)*(Pedidos_DB!E4:E110=B27)*Pedidos_DB!G4:G110) -> 523.5 | E27: =SUMIFS(Despesas_DB!H4:H99,Despesas_DB!C4:C99,$D$2,Despesas_DB!E4:E99,B27) -> 340 | F27: =D27-E27 -> 183.5 | G27: =IFERROR(F27/D27,0) -> 0.35052531
B28: Ampola de Fortalecimento | C28: =SUMPRODUCT((Pedidos_DB!C4:C110=$D$2)*(Pedidos_DB!E4:E110=B28)*Pedidos_DB!F4:F110) -> 18 | D28: =SUMPRODUCT((Pedidos_DB!C4:C110=$D$2)*(Pedidos_DB!E4:E110=B28)*Pedidos_DB!G4:G110) -> 230.4 | E28: =SUMIFS(Despesas_DB!H4:H99,Despesas_DB!C4:C99,$D$2,Despesas_DB!E4:E99,B28) -> 60 | F28: =D28-E28 -> 170.4 | G28: =IFERROR(F28/D28,0) -> 0.73958333
B29: Máscara Reparadora de Pontas | C29: =SUMPRODUCT((Pedidos_DB!C4:C110=$D$2)*(Pedidos_DB!E4:E110=B29)*Pedidos_DB!F4:F110) -> 5 | D29: =SUMPRODUCT((Pedidos_DB!C4:C110=$D$2)*(Pedidos_DB!E4:E110=B29)*Pedidos_DB!G4:G110) -> 192.5 | E29: =SUMIFS(Despesas_DB!H4:H99,Despesas_DB!C4:C99,$D$2,Despesas_DB!E4:E99,B29) -> 0 | F29: =D29-E29 -> 192.5 | G29: =IFERROR(F29/D29,0) -> 1
B30: Máscara de Reconstrução | C30: =SUMPRODUCT((Pedidos_DB!C4:C110=$D$2)*(Pedidos_DB!E4:E110=B30)*Pedidos_DB!F4:F110) -> 20 | D30: =SUMPRODUCT((Pedidos_DB!C4:C110=$D$2)*(Pedidos_DB!E4:E110=B30)*Pedidos_DB!G4:G110) -> 1000 | E30: =SUMIFS(Despesas_DB!H4:H99,Despesas_DB!C4:C99,$D$2,Despesas_DB!E4:E99,B30) -> 300 | F30: =D30-E30 -> 700 | G30: =IFERROR(F30/D30,0) -> 0.7
